<sdf version='1.4'>
  <model name='tiago'>
    <link name='base_footprint'>
      <pose>0 0 0 0 -0 0</pose>
      <inertial>
        <pose>-0.00983617 -0.0015008 0.21148 0 -0 0</pose>
        <mass>43.4016</mass>
        <inertia>
          <ixx>2.04327</ixx>
          <ixy>0.000744547</ixy>
          <ixz>0.109545</ixz>
          <iyy>2.13173</iyy>
          <iyz>0.0140814</iyz>
          <izz>0.688729</izz>
        </inertia>
      </inertial>
      <collision name='base_footprint_collision_base_antenna_left_link'>
        <pose>-0.201 0.1062 0.3785 0 -0 0</pose>
        <geometry>
          <cylinder>
            <length>0.17</length>
            <radius>0.005</radius>
          </cylinder>
        </geometry>
        <laser_retro>0</laser_retro>
        <surface>
          <contact>
            <ode>
              <kp>1e+08</kp>
              <kd>10</kd>
              <max_vel>10</max_vel>
              <min_depth>0.0005</min_depth>
            </ode>
          </contact>
          <friction>
            <ode>
              <mu>0.1</mu>
              <mu2>0.1</mu2>
              <fdir1>1 0 0</fdir1>
            </ode>
          </friction>
        </surface>
        <surface>
          <contact>
            <ode/>
          </contact>
          <friction>
            <ode/>
          </friction>
        </surface>
      </collision>
      <collision name='base_footprint_collision_base_antenna_right_link'>
        <pose>-0.201 -0.1062 0.3785 0 -0 0</pose>
        <geometry>
          <cylinder>
            <length>0.17</length>
            <radius>0.005</radius>
          </cylinder>
        </geometry>
        <laser_retro>0</laser_retro>
        <surface>
          <contact>
            <ode>
              <kp>1e+08</kp>
              <kd>10</kd>
              <max_vel>10</max_vel>
              <min_depth>0.0005</min_depth>
            </ode>
          </contact>
          <friction>
            <ode>
              <mu>0.1</mu>
              <mu2>0.1</mu2>
              <fdir1>1 0 0</fdir1>
            </ode>
          </friction>
        </surface>
        <surface>
          <contact>
            <ode/>
          </contact>
          <friction>
            <ode/>
          </friction>
        </surface>
      </collision>
      <collision name='base_footprint_collision_base_link'>
        <pose>0 0 0.0985 0 -0 0</pose>
        <geometry>
          <mesh>
            <scale>1 1 1</scale>
            <uri>file://tiago/pmb2_description/meshes/base/base_collision.dae</uri>
          </mesh>
        </geometry>
        <laser_retro>0</laser_retro>
        <surface>
          <contact>
            <ode>
              <kp>1e+08</kp>
              <kd>10</kd>
              <max_vel>10</max_vel>
              <min_depth>0.0005</min_depth>
            </ode>
          </contact>
          <friction>
            <ode>
              <mu>0.1</mu>
              <mu2>0.1</mu2>
              <fdir1>1 0 0</fdir1>
            </ode>
          </friction>
        </surface>
        <surface>
          <contact>
            <ode/>
          </contact>
          <friction>
            <ode/>
          </friction>
        </surface>
      </collision>
      <collision name='base_footprint_collision_torso_fixed_column_link'>
        <pose>-0.062 0 0.5685 0 -0 0</pose>
        <geometry>
          <box>
            <size>0.23 0.23 0.55</size>
          </box>
        </geometry>
        <laser_retro>0</laser_retro>
        <surface>
          <contact>
            <ode>
              <kp>1e+08</kp>
              <kd>10</kd>
              <max_vel>10</max_vel>
              <min_depth>0.0005</min_depth>
            </ode>
          </contact>
          <friction>
            <ode>
              <mu>0.1</mu>
              <mu2>0.1</mu2>
              <fdir1>1 0 0</fdir1>
            </ode>
          </friction>
        </surface>
        <surface>
          <contact>
            <ode/>
          </contact>
          <friction>
            <ode/>
          </friction>
        </surface>
      </collision>
      <collision name='base_footprint_collision_torso_fixed_link'>
        <pose>0.023 0 0.3115 0 -0 0</pose>
        <geometry>
          <box>
            <size>0.4 0.25 0.04</size>
          </box>
        </geometry>
        <laser_retro>0</laser_retro>
        <surface>
          <contact>
            <ode>
              <kp>1e+08</kp>
              <kd>10</kd>
              <max_vel>10</max_vel>
              <min_depth>0.0005</min_depth>
            </ode>
          </contact>
          <friction>
            <ode>
              <mu>0.1</mu>
              <mu2>0.1</mu2>
              <fdir1>1 0 0</fdir1>
            </ode>
          </friction>
        </surface>
      </collision>
      <collision name='base_footprint_collision_torso_fixed_link_1'>
        <pose>-0.062 0 0.3415 0 -0 0</pose>
        <geometry>
          <box>
            <size>0.25 0.25 0.1</size>
          </box>
        </geometry>
        <laser_retro>0</laser_retro>
        <surface>
          <contact>
            <ode>
              <kp>1e+08</kp>
              <kd>10</kd>
              <max_vel>10</max_vel>
              <min_depth>0.0005</min_depth>
            </ode>
          </contact>
          <friction>
            <ode>
              <mu>0.1</mu>
              <mu2>0.1</mu2>
              <fdir1>1 0 0</fdir1>
            </ode>
          </friction>
        </surface>
      </collision>
      <visual name='base_footprint_visual_base_antenna_left_link'>
        <pose>-0.201 0.1062 0.2935 0 -0 0</pose>
        <geometry>
          <mesh>
            <scale>1 1 1</scale>
            <uri>file://tiago/pmb2_description/meshes/objects/antenna.stl</uri>
          </mesh>
        </geometry>
        <material>
          <script>
            <name>Gazebo/Black</name>
            <uri>__default__</uri>
          </script>
        </material>
      </visual>
      <visual name='base_footprint_visual_base_antenna_right_link'>
        <pose>-0.201 -0.1062 0.2935 0 -0 0</pose>
        <geometry>
          <mesh>
            <scale>1 1 1</scale>
            <uri>file://tiago/pmb2_description/meshes/objects/antenna.stl</uri>
          </mesh>
        </geometry>
        <material>
          <script>
            <name>Gazebo/Black</name>
            <uri>__default__</uri>
          </script>
        </material>
      </visual>
      <visual name='base_footprint_visual_base_cover_link'>
        <pose>0 0 0.13 0 -0 0</pose>
        <geometry>
          <mesh>
            <scale>1 1 1</scale>
            <uri>file://tiago/pmb2_description/meshes/base/base_ring.stl</uri>
          </mesh>
        </geometry>
        <material>
          <script>
            <name>Gazebo/Orange</name>
            <uri>__default__</uri>
          </script>
        </material>
      </visual>
      <visual name='base_footprint_visual_base_laser_link'>
        <pose>0.202 0 0.0945 0 -0 0</pose>
        <geometry>
          <mesh>
            <scale>1 1 1</scale>
            <uri>file://tiago/pmb2_description/meshes/sensors/sick_tim551.stl</uri>
          </mesh>
        </geometry>
        <material>
          <script>
            <name>Gazebo/DarkGrey</name>
            <uri>__default__</uri>
          </script>
        </material>
      </visual>
      <visual name='base_footprint_visual_base_link'>
        <pose>0 0 0.0985 0 -0 0</pose>
        <geometry>
          <mesh>
            <scale>1 1 1</scale>
            <uri>file://tiago/pmb2_description/meshes/base/base.stl</uri>
          </mesh>
        </geometry>
        <material>
          <script>
            <name>Gazebo/White</name>
            <uri>__default__</uri>
          </script>
        </material>
      </visual>
      <visual name='base_footprint_visual_base_sonar_01_link'>
        <pose>-0.183 -0.183 0.2715 0 -0 -2.35619</pose>
        <geometry>
          <mesh>
            <scale>1 1 1</scale>
            <uri>file://tiago/pmb2_description/meshes/sensors/srf05.stl</uri>
          </mesh>
        </geometry>
        <material>
          <script>
            <name>Gazebo/DarkGrey</name>
            <uri>__default__</uri>
          </script>
        </material>
      </visual>
      <visual name='base_footprint_visual_base_sonar_02_link'>
        <pose>-0.259 0 0.2715 0 -0 -3.14159</pose>
        <geometry>
          <mesh>
            <scale>1 1 1</scale>
            <uri>file://tiago/pmb2_description/meshes/sensors/srf05.stl</uri>
          </mesh>
        </geometry>
        <material>
          <script>
            <name>Gazebo/DarkGrey</name>
            <uri>__default__</uri>
          </script>
        </material>
      </visual>
      <visual name='base_footprint_visual_base_sonar_03_link'>
        <pose>-0.183 0.183 0.2715 0 -0 2.35619</pose>
        <geometry>
          <mesh>
            <scale>1 1 1</scale>
            <uri>file://tiago/pmb2_description/meshes/sensors/srf05.stl</uri>
          </mesh>
        </geometry>
        <material>
          <script>
            <name>Gazebo/DarkGrey</name>
            <uri>__default__</uri>
          </script>
        </material>
      </visual>
      <visual name='base_footprint_visual_caster_back_left_1_link'>
        <pose>-0.1735 0.102 0.065 0 -0 0</pose>
        <geometry>
          <mesh>
            <scale>1 1 1</scale>
            <uri>file://tiago/pmb2_description/meshes/wheels/caster_1.stl</uri>
          </mesh>
        </geometry>
      </visual>
      <visual name='base_footprint_visual_caster_back_left_2_link'>
        <pose>-0.1895 0.102 0.025 -1.5708 0 0</pose>
        <geometry>
          <mesh>
            <scale>1 1 1</scale>
            <uri>file://tiago/pmb2_description/meshes/wheels/caster_2.stl</uri>
          </mesh>
        </geometry>
      </visual>
      <visual name='base_footprint_visual_caster_back_right_1_link'>
        <pose>-0.1735 -0.102 0.065 0 -0 0</pose>
        <geometry>
          <mesh>
            <scale>1 1 1</scale>
            <uri>file://tiago/pmb2_description/meshes/wheels/caster_1.stl</uri>
          </mesh>
        </geometry>
      </visual>
      <visual name='base_footprint_visual_caster_back_right_2_link'>
        <pose>-0.1895 -0.102 0.025 -1.5708 0 0</pose>
        <geometry>
          <mesh>
            <scale>1 1 1</scale>
            <uri>file://tiago/pmb2_description/meshes/wheels/caster_2.stl</uri>
          </mesh>
        </geometry>
      </visual>
      <visual name='base_footprint_visual_caster_front_left_1_link'>
        <pose>0.1695 0.102 0.065 0 -0 0</pose>
        <geometry>
          <mesh>
            <scale>1 1 1</scale>
            <uri>file://tiago/pmb2_description/meshes/wheels/caster_1.stl</uri>
          </mesh>
        </geometry>
      </visual>
      <visual name='base_footprint_visual_caster_front_left_2_link'>
        <pose>0.1535 0.102 0.025 -1.5708 0 0</pose>
        <geometry>
          <mesh>
            <scale>1 1 1</scale>
            <uri>file://tiago/pmb2_description/meshes/wheels/caster_2.stl</uri>
          </mesh>
        </geometry>
      </visual>
      <visual name='base_footprint_visual_caster_front_right_1_link'>
        <pose>0.1695 -0.102 0.065 0 -0 0</pose>
        <geometry>
          <mesh>
            <scale>1 1 1</scale>
            <uri>file://tiago/pmb2_description/meshes/wheels/caster_1.stl</uri>
          </mesh>
        </geometry>
      </visual>
      <visual name='base_footprint_visual_caster_front_right_2_link'>
        <pose>0.1535 -0.102 0.025 -1.5708 0 0</pose>
        <geometry>
          <mesh>
            <scale>1 1 1</scale>
            <uri>file://tiago/pmb2_description/meshes/wheels/caster_2.stl</uri>
          </mesh>
        </geometry>
      </visual>
      <visual name='base_footprint_visual_torso_fixed_column_link'>
        <pose>-0.062 0 0.5685 0 -0 0</pose>
        <geometry>
          <box>
            <size>0.18 0.2 0.55</size>
          </box>
        </geometry>
        <material>
          <script>
            <name>Gazebo/DarkGrey</name>
            <uri>__default__</uri>
          </script>
        </material>
      </visual>
      <visual name='base_footprint_visual_torso_fixed_link'>
        <pose>-0.062 0 0.2915 0 -0 0</pose>
        <geometry>
          <mesh>
            <scale>1 1 1</scale>
            <uri>file://tiago/tiago_description/meshes/torso/torso_fix.stl</uri>
          </mesh>
        </geometry>
      </visual>
      <velocity_decay>
        <linear>0</linear>
        <angular>0</angular>
      </velocity_decay>
      <velocity_decay>
        <linear>0</linear>
        <angular>0</angular>
      </velocity_decay>
      <velocity_decay>
        <linear>0</linear>
        <angular>0</angular>
      </velocity_decay>
      <velocity_decay>
        <linear>0</linear>
        <angular>0</angular>
      </velocity_decay>
      <velocity_decay>
        <linear>0</linear>
        <angular>0</angular>
      </velocity_decay>
      <sensor name='imu_sensor' type='imu'>
        <always_on>1</always_on>
        <update_rate>1000</update_rate>
        <imu>
          <noise>
            <type>gaussian</type>
            <rate>
              <mean>0</mean>
              <stddev>0.0002</stddev>
              <bias_mean>7.5e-06</bias_mean>
              <bias_stddev>8e-07</bias_stddev>
            </rate>
            <accel>
              <mean>0</mean>
              <stddev>0.017</stddev>
              <bias_mean>0.1</bias_mean>
              <bias_stddev>0.001</bias_stddev>
            </accel>
          </noise>
        </imu>
        <pose>0.10171 0 0.21132 0 0 -1.5708</pose>
      </sensor>
      <velocity_decay>
        <linear>0</linear>
        <angular>0</angular>
      </velocity_decay>
      <sensor name='base_imu_sensor' type='imu'>
        <always_on>1</always_on>
        <update_rate>100</update_rate>
        <imu>
          <noise>
            <type>gaussian</type>
            <rate>
              <mean>0</mean>
              <stddev>0.0002</stddev>
              <bias_mean>7.5e-06</bias_mean>
              <bias_stddev>8e-07</bias_stddev>
            </rate>
            <accel>
              <mean>0</mean>
              <stddev>0.017</stddev>
              <bias_mean>0.1</bias_mean>
              <bias_stddev>0.001</bias_stddev>
            </accel>
          </noise>
        </imu>
        <pose>0.10171 0 0.21132 0 0 -1.5708</pose>
      </sensor>
      <velocity_decay>
        <linear>0</linear>
        <angular>0</angular>
      </velocity_decay>
      <sensor name='base_laser' type='ray'>
        <update_rate>10</update_rate>
        <visualize>1</visualize>
        <ray>
          <scan>
            <horizontal>
              <samples>640</samples>
              <resolution>1</resolution>
              <min_angle>-1.91986</min_angle>
              <max_angle>1.91986</max_angle>
            </horizontal>
          </scan>
          <range>
            <min>0.05</min>
            <max>10</max>
            <resolution>0.001</resolution>
          </range>
        </ray>
		<!-- 0.202 0 0.0945 0 -0 0 -->
        <pose>0.350 0 0.0945 0 -0 0</pose>
      	<!-- Attach the plugin to this model -->
		<!--      	
		<plugin name="laserScanPlugin" filename="liblaserScanPlugin.so">
      	</plugin>
		-->
	  </sensor>
      <velocity_decay>
        <linear>0</linear>
        <angular>0</angular>
      </velocity_decay>
      <sensor name='base_sonar_01' type='ray'>
        <update_rate>5</update_rate>
        <visualize>0</visualize>
        <ray>
          <scan>
            <horizontal>
              <samples>5</samples>
              <resolution>1</resolution>
              <min_angle>-0.25</min_angle>
              <max_angle>0.25</max_angle>
            </horizontal>
            <vertical>
              <samples>5</samples>
              <resolution>1</resolution>
              <min_angle>-0.25</min_angle>
              <max_angle>0.25</max_angle>
            </vertical>
          </scan>
          <range>
            <min>0.02</min>
            <max>2</max>
            <resolution>0.01</resolution>
          </range>
        </ray>
        <pose>-0.183 -0.183 0.2715 0 -0 -2.35619</pose>
      </sensor>
      <velocity_decay>
        <linear>0</linear>
        <angular>0</angular>
      </velocity_decay>
      <sensor name='base_sonar_02' type='ray'>
        <update_rate>5</update_rate>
        <visualize>0</visualize>
        <ray>
          <scan>
            <horizontal>
              <samples>5</samples>
              <resolution>1</resolution>
              <min_angle>-0.25</min_angle>
              <max_angle>0.25</max_angle>
            </horizontal>
            <vertical>
              <samples>5</samples>
              <resolution>1</resolution>
              <min_angle>-0.25</min_angle>
              <max_angle>0.25</max_angle>
            </vertical>
          </scan>
          <range>
            <min>0.02</min>
            <max>2</max>
            <resolution>0.01</resolution>
          </range>
        </ray>
        <pose>-0.259 0 0.2715 0 -0 -3.14159</pose>
      </sensor>
      <velocity_decay>
        <linear>0</linear>
        <angular>0</angular>
      </velocity_decay>
      <sensor name='base_sonar_03' type='ray'>
        <update_rate>5</update_rate>
        <visualize>0</visualize>
        <ray>
          <scan>
            <horizontal>
              <samples>5</samples>
              <resolution>1</resolution>
              <min_angle>-0.25</min_angle>
              <max_angle>0.25</max_angle>
            </horizontal>
            <vertical>
              <samples>5</samples>
              <resolution>1</resolution>
              <min_angle>-0.25</min_angle>
              <max_angle>0.25</max_angle>
            </vertical>
          </scan>
          <range>
            <min>0.02</min>
            <max>2</max>
            <resolution>0.01</resolution>
          </range>
        </ray>
        <pose>-0.183 0.183 0.2715 0 -0 2.35619</pose>
      </sensor>
      <velocity_decay>
        <linear>0</linear>
        <angular>0</angular>
      </velocity_decay>
      <gravity>1</gravity>
      <velocity_decay>
        <linear>0</linear>
        <angular>0</angular>
      </velocity_decay>
      <self_collide>0</self_collide>
    </link>
    <link name='torso_lift_link'>
      <pose>-0.062 0 1.8785 0 -0 0</pose>
      <inertial>
        <pose>0.04361 -0.00116 -0.17334 0 -0 0</pose>
        <mass>6.93198</mass>
        <inertia>
          <ixx>0.24487</ixx>
          <ixy>-0.001456</ixy>
          <ixz>-0.009742</ixz>
          <iyy>0.249269</iyy>
          <iyz>0.008281</iyz>
          <izz>0.090395</izz>
        </inertia>
      </inertial>
      <collision name='torso_lift_link_collision'>
        <pose>0 0 0 0 -0 0</pose>
        <geometry>
          <mesh>
            <scale>1 1 1</scale>
            <uri>file://tiago/tiago_description/meshes/torso/torso_lift_collision.dae</uri>
          </mesh>
        </geometry>
      </collision>
      <visual name='torso_lift_link_visual'>
        <pose>0 0 0 0 -0 0</pose>
        <geometry>
          <mesh>
            <scale>1 1 1</scale>
            <uri>file://tiago/tiago_description/meshes/torso/torso_lift_with_arm.stl</uri>
          </mesh>
        </geometry>
      </visual>
      <velocity_decay>
        <linear>0</linear>
        <angular>0</angular>
      </velocity_decay>
    </link>
    <joint name='torso_lift_joint' type='prismatic'>
      <child>torso_lift_link</child>
      <parent>base_footprint</parent>
      <axis>
        <xyz>0 0 1</xyz>
        <limit>
          <lower>0</lower>
          <upper>0.35</upper>
          <effort>2000</effort>
          <velocity>0.07</velocity>
        </limit>
        <dynamics>
          <damping>1000</damping>
        </dynamics>
      </axis>
    </joint>
    <link name='arm_1_link'>
      <pose>0.09305 0.014 1.7275 0 0 -1.5708</pose>
      <inertial>
        <pose>0.08169 0.01822 -0.01884 0 -0 0</pose>
        <mass>2.31325</mass>
        <inertia>
          <ixx>0.002694</ixx>
          <ixy>0.001157</ixy>
          <ixz>-0.001423</ixz>
          <iyy>0.007041</iyy>
          <iyz>-0.000312</iyz>
          <izz>0.007312</izz>
        </inertia>
      </inertial>
      <collision name='arm_1_link_collision'>
        <pose>0 0 0 0 -0 0</pose>
        <geometry>
          <mesh>
            <scale>1 1 1</scale>
            <uri>file://tiago/tiago_description/meshes/arm/arm_1_collision.dae</uri>
          </mesh>
        </geometry>
        <surface>
          <contact>
            <ode/>
          </contact>
          <friction>
            <ode/>
          </friction>
        </surface>
        <surface>
          <contact>
            <ode/>
          </contact>
          <friction>
            <ode>
              <mu>0.9</mu>
              <mu2>0.9</mu2>
            </ode>
          </friction>
        </surface>
      </collision>
      <visual name='arm_1_link_visual'>
        <pose>0 0 0 0 -0 0</pose>
        <geometry>
          <mesh>
            <scale>1 1 1</scale>
            <uri>file://tiago/tiago_description/meshes/arm/arm_1.stl</uri>
          </mesh>
        </geometry>
        <material>
          <script>
            <name>Gazebo/Orange</name>
            <uri>__default__</uri>
          </script>
        </material>
        <material>
          <script>
            <name>Gazebo/DarkGrey</name>
            <uri>__default__</uri>
          </script>
        </material>
      </visual>
      <velocity_decay>
        <linear>0</linear>
        <angular>0</angular>
      </velocity_decay>
      <gravity>1</gravity>
      <velocity_decay>
        <linear>0</linear>
        <angular>0</angular>
      </velocity_decay>
      <self_collide>0</self_collide>
    </link>
    <joint name='arm_1_joint' type='revolute'>
      <child>arm_1_link</child>
      <parent>torso_lift_link</parent>
      <axis>
        <xyz>0 0 1</xyz>
        <limit>
          <lower>0</lower>
          <upper>2.74889</upper>
          <effort>39</effort>
          <velocity>2.7</velocity>
        </limit>
        <dynamics>
          <damping>1</damping>
        </dynamics>
      </axis>
      <physics>
        <ode>
          <implicit_spring_damper>1</implicit_spring_damper>
          <cfm_damping>1</cfm_damping>
          <limit>
            <cfm>0</cfm>
            <erp>0.2</erp>
          </limit>
        </ode>
      </physics>
    </joint>
    <link name='arm_2_link'>
      <pose>0.10955 -0.111 1.6965 1.5708 5.55112e-17 -1.5708</pose>
      <inertial>
        <pose>-0.03609 -6e-05 0.01649 0 -0 0</pose>
        <mass>1.10224</mass>
        <inertia>
          <ixx>0.001146</ixx>
          <ixy>1e-06</ixy>
          <ixz>0.000435</ixz>
          <iyy>0.002182</iyy>
          <iyz>-1e-06</iyz>
          <izz>0.002373</izz>
        </inertia>
      </inertial>
      <collision name='arm_2_link_collision'>
        <pose>0 0 0 0 -0 0</pose>
        <geometry>
          <mesh>
            <scale>1 1 1</scale>
            <uri>file://tiago/tiago_description/meshes/arm/arm_2_collision.dae</uri>
          </mesh>
        </geometry>
        <surface>
          <contact>
            <ode/>
          </contact>
          <friction>
            <ode>
              <mu>0.9</mu>
              <mu2>0.9</mu2>
            </ode>
          </friction>
        </surface>
      </collision>
      <visual name='arm_2_link_visual'>
        <pose>0 0 0 0 -0 0</pose>
        <geometry>
          <mesh>
            <scale>1 1 1</scale>
            <uri>file://tiago/tiago_description/meshes/arm/arm_2.stl</uri>
          </mesh>
        </geometry>
        <material>
          <script>
            <name>Gazebo/DarkGrey</name>
            <uri>__default__</uri>
          </script>
        </material>
      </visual>
      <gravity>1</gravity>
      <velocity_decay>
        <linear>0</linear>
        <angular>0</angular>
      </velocity_decay>
      <self_collide>0</self_collide>
    </link>
    <joint name='arm_2_joint' type='revolute'>
      <child>arm_2_link</child>
      <parent>arm_1_link</parent>
      <axis>
        <xyz>-1 -4.89656e-12 4.89658e-12</xyz>
        <limit>
          <lower>-1.5708</lower>
          <upper>1.09083</upper>
          <effort>39</effort>
          <velocity>3.66</velocity>
        </limit>
        <dynamics>
          <damping>1</damping>
        </dynamics>
      </axis>
      <physics>
        <ode>
          <implicit_spring_damper>1</implicit_spring_damper>
          <cfm_damping>1</cfm_damping>
          <limit>
            <cfm>0</cfm>
            <erp>0.2</erp>
          </limit>
        </ode>
      </physics>
    </joint>
    <link name='arm_3_link'>
      <pose>0.10805 -0.2005 1.6965 2.3562 -1.57079 2.35621</pose>
      <inertial>
        <pose>0.00752 0.00244 0.12957 0 -0 0</pose>
        <mass>2.4246</mass>
        <inertia>
          <ixx>0.014418</ixx>
          <ixy>8.4e-05</ixy>
          <ixz>0.001143</ixz>
          <iyy>0.014788</iyy>
          <iyz>0.000642</iyz>
          <izz>0.00256</izz>
        </inertia>
      </inertial>
      <collision name='arm_3_link_collision'>
        <pose>0 0 0 0 -0 0</pose>
        <geometry>
          <mesh>
            <scale>1 1 1</scale>
            <uri>file://tiago/tiago_description/meshes/arm/arm_3_collision.dae</uri>
          </mesh>
        </geometry>
        <surface>
          <contact>
            <ode/>
          </contact>
          <friction>
            <ode>
              <mu>0.9</mu>
              <mu2>0.9</mu2>
            </ode>
          </friction>
        </surface>
      </collision>
      <visual name='arm_3_link_visual'>
        <pose>0 0 0 0 -0 0</pose>
        <geometry>
          <mesh>
            <scale>1 1 1</scale>
            <uri>file://tiago/tiago_description/meshes/arm/arm_3.stl</uri>
          </mesh>
        </geometry>
        <material>
          <script>
            <name>Gazebo/DarkGrey</name>
            <uri>__default__</uri>
          </script>
        </material>
      </visual>
      <gravity>1</gravity>
      <velocity_decay>
        <linear>0</linear>
        <angular>0</angular>
      </velocity_decay>
      <self_collide>0</self_collide>
    </link>
    <joint name='arm_3_joint' type='revolute'>
      <child>arm_3_link</child>
      <parent>arm_2_link</parent>
      <axis>
        <xyz>-9.79317e-12 1 4.89653e-12</xyz>
        <limit>
          <lower>-3.53429</lower>
          <upper>1.5708</upper>
          <effort>17.86</effort>
          <velocity>4.58</velocity>
        </limit>
        <dynamics>
          <damping>1</damping>
        </dynamics>
      </axis>
      <physics>
        <ode>
          <implicit_spring_damper>1</implicit_spring_damper>
          <cfm_damping>1</cfm_damping>
          <limit>
            <cfm>0</cfm>
            <erp>0.2</erp>
          </limit>
        </ode>
      </physics>
    </joint>
    <link name='arm_4_link'>
      <pose>0.08105 -0.4225 1.6765 1.5708 -9.79322e-12 1.5708</pose>
      <inertial>
        <pose>0.07426 -0.01306 0.01549 0 -0 0</pose>
        <mass>1.45429</mass>
        <inertia>
          <ixx>0.001953</ixx>
          <ixy>-0.000596</ixy>
          <ixz>0.00088</ixz>
          <iyy>0.007097</iyy>
          <iyz>-0.000171</iyz>
          <izz>0.007405</izz>
        </inertia>
      </inertial>
      <collision name='arm_4_link_collision'>
        <pose>0 0 0 0 -0 0</pose>
        <geometry>
          <mesh>
            <scale>1 1 1</scale>
            <uri>file://tiago/tiago_description/meshes/arm/arm_4_collision.dae</uri>
          </mesh>
        </geometry>
        <surface>
          <contact>
            <ode/>
          </contact>
          <friction>
            <ode>
              <mu>0.9</mu>
              <mu2>0.9</mu2>
            </ode>
          </friction>
        </surface>
      </collision>
      <visual name='arm_4_link_visual'>
        <pose>0 0 0 0 -0 0</pose>
        <geometry>
          <mesh>
            <scale>1 1 1</scale>
            <uri>file://tiago/tiago_description/meshes/arm/arm_4.stl</uri>
          </mesh>
        </geometry>
        <material>
          <script>
            <name>Gazebo/DarkGrey</name>
            <uri>__default__</uri>
          </script>
        </material>
      </visual>
      <gravity>1</gravity>
      <velocity_decay>
        <linear>0</linear>
        <angular>0</angular>
      </velocity_decay>
      <self_collide>0</self_collide>
    </link>
    <joint name='arm_4_joint' type='revolute'>
      <child>arm_4_link</child>
      <parent>arm_3_link</parent>
      <axis>
        <xyz>1 9.79317e-12 -9.79322e-12</xyz>
        <limit>
          <lower>-0.392699</lower>
          <upper>2.35619</upper>
          <effort>17.86</effort>
          <velocity>4.58</velocity>
        </limit>
        <dynamics>
          <damping>1</damping>
        </dynamics>
      </axis>
      <physics>
        <ode>
          <implicit_spring_damper>1</implicit_spring_damper>
          <cfm_damping>1</cfm_damping>
          <limit>
            <cfm>0</cfm>
            <erp>0.2</erp>
          </limit>
        </ode>
      </physics>
    </joint>
    <link name='arm_5_link'>
      <pose>0.10805 -0.5845 1.6965 1.5708 9.79314e-12 1.46898e-11</pose>
      <inertial>
        <pose>3e-05 -0.00028 0.07831 0 -0 0</pose>
        <mass>1.07424</mass>
        <inertia>
          <ixx>0.00168</ixx>
          <ixy>1e-06</ixy>
          <ixz>-1.5e-05</ixz>
          <iyy>0.001603</iyy>
          <iyz>-1.9e-05</iyz>
          <izz>0.000404</izz>
        </inertia>
      </inertial>
      <collision name='arm_5_link_collision'>
        <pose>0 0 0 0 -0 0</pose>
        <geometry>
          <mesh>
            <scale>1 1 1</scale>
            <uri>file://tiago/tiago_description/meshes/arm/arm_5_collision.dae</uri>
          </mesh>
        </geometry>
        <surface>
          <contact>
            <ode/>
          </contact>
          <friction>
            <ode>
              <mu>0.9</mu>
              <mu2>0.9</mu2>
            </ode>
          </friction>
        </surface>
      </collision>
      <visual name='arm_5_link_visual'>
        <pose>0 0 0 0 -0 0</pose>
        <geometry>
          <mesh>
            <scale>1 1 1</scale>
            <uri>file://tiago/tiago_description/meshes/arm/arm_5.stl</uri>
          </mesh>
        </geometry>
      </visual>
      <gravity>1</gravity>
      <velocity_decay>
        <linear>0</linear>
        <angular>0</angular>
      </velocity_decay>
      <self_collide>0</self_collide>
    </link>
    <joint name='arm_5_joint' type='revolute'>
      <child>arm_5_link</child>
      <parent>arm_4_link</parent>
      <axis>
        <xyz>1.46898e-11 -1 -9.79306e-12</xyz>
        <limit>
          <lower>-2.0944</lower>
          <upper>2.0944</upper>
          <effort>3</effort>
          <velocity>1.95</velocity>
        </limit>
        <dynamics>
          <damping>1</damping>
        </dynamics>
      </axis>
      <physics>
        <ode>
          <implicit_spring_damper>1</implicit_spring_damper>
          <cfm_damping>1</cfm_damping>
          <limit>
            <cfm>0</cfm>
            <erp>0.2</erp>
          </limit>
        </ode>
      </physics>
    </joint>
    <link name='arm_6_link'>
      <pose>0.10805 -0.7345 1.6965 -4.89657e-12 1.46895e-11 -1.5708</pose>
      <inertial>
        <pose>0.00531 0.00021 2e-05 0 -0 0</pose>
        <mass>0.28722</mass>
        <inertia>
          <ixx>5.9e-05</ixx>
          <ixy>-0</ixy>
          <ixz>-0</ixz>
          <iyy>0.000106</iyy>
          <iyz>0</iyz>
          <izz>0.000126</izz>
        </inertia>
      </inertial>
      <collision name='arm_6_link_collision'>
        <pose>0 0 0 0 -0 0</pose>
        <geometry>
          <mesh>
            <scale>1 1 1</scale>
            <uri>file://tiago/tiago_description/meshes/arm/arm_6_collision.dae</uri>
          </mesh>
        </geometry>
        <surface>
          <contact>
            <ode/>
          </contact>
          <friction>
            <ode>
              <mu>0.9</mu>
              <mu2>0.9</mu2>
            </ode>
          </friction>
        </surface>
      </collision>
      <visual name='arm_6_link_visual'>
        <pose>0 0 0 0 -0 0</pose>
        <geometry>
          <mesh>
            <scale>1 1 1</scale>
            <uri>file://tiago/tiago_description/meshes/arm/arm_6.stl</uri>
          </mesh>
        </geometry>
      </visual>
      <gravity>1</gravity>
      <velocity_decay>
        <linear>0</linear>
        <angular>0</angular>
      </velocity_decay>
      <self_collide>0</self_collide>
    </link>
    <joint name='arm_6_joint' type='revolute'>
      <child>arm_6_link</child>
      <parent>arm_5_link</parent>
      <axis>
        <xyz>4.89657e-12 -1.46895e-11 1</xyz>
        <limit>
          <lower>-1.41372</lower>
          <upper>1.41372</upper>
          <effort>6.6</effort>
          <velocity>1.76</velocity>
        </limit>
        <dynamics>
          <damping>1</damping>
        </dynamics>
      </axis>
      <physics>
        <ode>
          <implicit_spring_damper>1</implicit_spring_damper>
          <cfm_damping>1</cfm_damping>
          <limit>
            <cfm>0</cfm>
            <erp>0.2</erp>
          </limit>
        </ode>
      </physics>
    </joint>
    <link name='arm_7_link'>
		<!-- 
		z = 0.6965
		-->
      <pose>0.10805 -0.7345 1.6965 1.5708 4.89657e-12 9.79322e-12</pose>
      <inertial>
        <pose>-0.00114749 0.00108214 0.0926414 0 -0 0</pose>
        <mass>0.75945</mass>
        <inertia>
          <ixx>0.0022212</ixx>
          <ixy>8.48741e-06</ixy>
          <ixz>3.88063e-05</ixz>
          <iyy>0.00206519</iyy>
          <iyz>-1.81786e-05</iyz>
          <izz>0.000410998</izz>
        </inertia>
      </inertial>
      <collision name='arm_7_link_collision_arm_tool_link'>
        <pose>-4.89691e-15 2.1684e-19 0.047 4.89673e-12 -4.89673e-12 -1.5708</pose>
        <geometry>
          <cylinder>
            <length>0.005</length>
            <radius>0.005</radius>
          </cylinder>
        </geometry>
        <surface>
          <contact>
            <ode/>
          </contact>
          <friction>
            <ode>
              <mu>0.9</mu>
              <mu2>0.9</mu2>
            </ode>
          </friction>
        </surface>
      </collision>
      <collision name='arm_7_link_collision_hand_palm_link'>
        <pose>-1.63064e-13 6.23113e-14 0.066575 -0.785373 -1.57079 -0.785413</pose>
        <geometry>
          <mesh>
            <scale>1 1 1</scale>
            <uri>file://tiago/hey5_description/meshes/palm_collision.stl</uri>
          </mesh>
        </geometry>
        <surface>
          <contact>
            <ode/>
          </contact>
          <friction>
            <ode>
              <mu>0.9</mu>
              <mu2>0.9</mu2>
            </ode>
          </friction>
        </surface>
        <surface>
          <contact>
            <ode/>
          </contact>
          <friction>
            <ode/>
          </friction>
        </surface>
      </collision>
      <collision name='arm_7_link_collision_hand_safety_box'>
        <pose>0.02 0.02 0.166575 -0.785373 -1.57079 -0.785413</pose>
        <geometry>
          <box>
            <size>0.2 0.115 0.18</size>
          </box>
        </geometry>
        <surface>
          <contact>
            <ode/>
          </contact>
          <friction>
            <ode>
              <mu>0.9</mu>
              <mu2>0.9</mu2>
            </ode>
          </friction>
        </surface>
      </collision>
      <collision name='arm_7_link_collision_wrist_ft_link'>
        <pose>-3.84415e-14 8.67362e-19 0.05385 -4.89669e-12 -9.79328e-12 -4.68969e-12</pose>
        <geometry>
          <cylinder>
            <length>0.0157</length>
            <radius>0.0225</radius>
          </cylinder>
        </geometry>
        <surface>
          <contact>
            <ode/>
          </contact>
          <friction>
            <ode>
              <mu>0.9</mu>
              <mu2>0.9</mu2>
            </ode>
          </friction>
        </surface>
      </collision>
      <collision name='arm_7_link_collision_wrist_ft_tool_link'>
        <pose>-1.63064e-13 6.23113e-14 0.066575 4.89678e-12 -9.79359e-12 -1.5708</pose>
        <geometry>
          <cylinder>
            <length>0.00975</length>
            <radius>0.025</radius>
          </cylinder>
        </geometry>
        <surface>
          <contact>
            <ode/>
          </contact>
          <friction>
            <ode>
              <mu>0.9</mu>
              <mu2>0.9</mu2>
            </ode>
          </friction>
        </surface>
      </collision>
      <visual name='arm_7_link_visual_arm_tool_link'>
        <pose>-4.89691e-15 2.1684e-19 0.047 4.89673e-12 -4.89673e-12 -1.5708</pose>
        <geometry>
          <cylinder>
            <length>0.005</length>
            <radius>0.005</radius>
          </cylinder>
        </geometry>
      </visual>
      <visual name='arm_7_link_visual_hand_palm_link'>
        <pose>-1.63064e-13 6.23113e-14 0.066575 -0.785373 -1.57079 -0.785413</pose>
        <geometry>
          <mesh>
            <scale>1 1 1</scale>
            <uri>file://tiago/hey5_description/meshes/palm.stl</uri>
          </mesh>
        </geometry>
        <material>
          <script>
            <name>Gazebo/Black</name>
            <uri>__default__</uri>
          </script>
        </material>
      </visual>
      <visual name='arm_7_link_visual_wrist_ft_link'>
        <pose>-3.84415e-14 8.67362e-19 0.05385 -4.89669e-12 -9.79328e-12 -4.68969e-12</pose>
        <geometry>
          <cylinder>
            <length>0.0157</length>
            <radius>0.0225</radius>
          </cylinder>
        </geometry>
      </visual>
      <visual name='arm_7_link_visual_wrist_ft_tool_link'>
        <pose>-1.63064e-13 6.23113e-14 0.066575 4.89678e-12 -9.79359e-12 -1.5708</pose>
        <geometry>
          <cylinder>
            <length>0.00975</length>
            <radius>0.025</radius>
          </cylinder>
        </geometry>
      </visual>
      <velocity_decay>
        <linear>0</linear>
        <angular>0</angular>
      </velocity_decay>
      <gravity>1</gravity>
      <velocity_decay>
        <linear>0</linear>
        <angular>0</angular>
      </velocity_decay>
      <self_collide>0</self_collide>
    </link>
    <joint name='arm_7_joint' type='revolute'>
      <child>arm_7_link</child>
      <parent>arm_6_link</parent>
      <axis>
        <xyz>9.79322e-12 -1 -9.79306e-12</xyz>
        <limit>
          <lower>-2.0944</lower>
          <upper>2.0944</upper>
          <effort>6.6</effort>
          <velocity>1.76</velocity>
        </limit>
        <dynamics>
          <damping>1</damping>
        </dynamics>
      </axis>
      <physics>
        <provide_feedback>1</provide_feedback>
        <ode>
          <provide_feedback>1</provide_feedback>
          <implicit_spring_damper>1</implicit_spring_damper>
          <cfm_damping>1</cfm_damping>
          <limit>
            <cfm>0</cfm>
            <erp>0.2</erp>
          </limit>
        </ode>
      </physics>
    </joint>
    <link name='hand_index_abd_link'>
      <pose>0.11225 -0.927575 1.723 -1.5708 -0.523599 -1.5708</pose>
      <inertial>
        <pose>-0.0018 0 0.0028 0 -0 0</pose>
        <mass>0.018</mass>
        <inertia>
          <ixx>0.001</ixx>
          <ixy>0</ixy>
          <ixz>0</ixz>
          <iyy>0.001</iyy>
          <iyz>0</iyz>
          <izz>0.001</izz>
        </inertia>
      </inertial>
      <collision name='hand_index_abd_link_collision'>
        <pose>0 0 0 0 -0 0</pose>
        <geometry>
          <mesh>
            <scale>1 1 1</scale>
            <uri>file://tiago/hey5_description/meshes/finger_abd_collision.stl</uri>
          </mesh>
        </geometry>
        <surface>
          <contact>
            <ode/>
          </contact>
          <friction>
            <ode/>
          </friction>
        </surface>
      </collision>
      <visual name='hand_index_abd_link_visual'>
        <pose>0 0 0 0 -0 0</pose>
        <geometry>
          <mesh>
            <scale>1 1 1</scale>
            <uri>file://tiago/hey5_description/meshes/finger_abd_collision.stl</uri>
          </mesh>
        </geometry>
        <material>
          <script>
            <name>Gazebo/Black</name>
            <uri>__default__</uri>
          </script>
        </material>
      </visual>
      <gravity>1</gravity>
      <velocity_decay>
        <linear>0</linear>
        <angular>0</angular>
      </velocity_decay>
      <self_collide>0</self_collide>
    </link>
    <joint name='hand_index_abd_joint' type='revolute'>
      <child>hand_index_abd_link</child>
      <parent>arm_7_link</parent>
      <axis>
        <xyz>1 7.34499e-12 -4.48808e-13</xyz>
        <limit>
          <lower>-0.523599</lower>
          <upper>0.523599</upper>
          <effort>2</effort>
          <velocity>2</velocity>
        </limit>
        <dynamics>
          <damping>0.5</damping>
        </dynamics>
      </axis>
    </joint>
    <link name='hand_index_virtual_1_link'>
      <pose>0.11225 -0.935369 1.7275 -5.41487e-12 -0.523599 -1.5708</pose>
      <inertial>
        <pose>0.0065 0 0 0 -0 0</pose>
        <mass>0.01</mass>
        <inertia>
          <ixx>0.001</ixx>
          <ixy>0</ixy>
          <ixz>0</ixz>
          <iyy>0.001</iyy>
          <iyz>0</iyz>
          <izz>0.001</izz>
        </inertia>
      </inertial>
      <collision name='hand_index_virtual_1_link_collision'>
        <pose>0 0 0 0 -0 0</pose>
        <geometry>
          <box>
            <size>0.013 0.002 0.012</size>
          </box>
        </geometry>
        <surface>
          <contact>
            <ode/>
          </contact>
          <friction>
            <ode/>
          </friction>
        </surface>
      </collision>
      <visual name='hand_index_virtual_1_link_visual'>
        <pose>0.0065 0 0 0 -0 0</pose>
        <geometry>
          <box>
            <size>0.013 0.002 0.012</size>
          </box>
        </geometry>
        <material>
          <script>
            <name>Gazebo/Black</name>
            <uri>__default__</uri>
          </script>
        </material>
      </visual>
      <gravity>1</gravity>
      <velocity_decay>
        <linear>0</linear>
        <angular>0</angular>
      </velocity_decay>
      <self_collide>0</self_collide>
    </link>
    <joint name='hand_index_virtual_1_joint' type='revolute'>
      <child>hand_index_virtual_1_link</child>
      <parent>hand_index_abd_link</parent>
      <axis>
        <xyz>1.61279e-12 0.5 0.866025</xyz>
        <limit>
          <lower>0</lower>
          <upper>0.785398</upper>
          <effort>2</effort>
          <velocity>2</velocity>
        </limit>
        <dynamics>
          <damping>0.5</damping>
        </dynamics>
      </axis>
    </joint>
    <link name='hand_index_flex_1_link'>
      <pose>0.11225 -0.946628 1.734 -5.41487e-12 -0.523599 -1.5708</pose>
      <inertial>
        <pose>0.0047 0.0031 0 0 -0 0</pose>
        <mass>0.009</mass>
        <inertia>
          <ixx>0.001</ixx>
          <ixy>0</ixy>
          <ixz>0</ixz>
          <iyy>0.001</iyy>
          <iyz>0</iyz>
          <izz>0.001</izz>
        </inertia>
      </inertial>
      <collision name='hand_index_flex_1_link_collision'>
        <pose>0 0 0 0 -0 0</pose>
        <geometry>
          <mesh>
            <scale>1 1 1</scale>
            <uri>file://tiago/hey5_description/meshes/finger_flex_collision.stl</uri>
          </mesh>
        </geometry>
        <surface>
          <contact>
            <ode/>
          </contact>
          <friction>
            <ode/>
          </friction>
        </surface>
      </collision>
      <visual name='hand_index_flex_1_link_visual'>
        <pose>0 0 0 0 -0 0</pose>
        <geometry>
          <mesh>
            <scale>1 1 1</scale>
            <uri>file://tiago/hey5_description/meshes/finger_flex_collision.stl</uri>
          </mesh>
        </geometry>
        <material>
          <script>
            <name>Gazebo/Black</name>
            <uri>__default__</uri>
          </script>
        </material>
      </visual>
      <gravity>1</gravity>
      <velocity_decay>
        <linear>0</linear>
        <angular>0</angular>
      </velocity_decay>
      <self_collide>0</self_collide>
    </link>
    <joint name='hand_index_flex_1_joint' type='revolute'>
      <child>hand_index_flex_1_link</child>
      <parent>hand_index_virtual_1_link</parent>
      <axis>
        <xyz>1.61279e-12 0.5 0.866025</xyz>
        <limit>
          <lower>0</lower>
          <upper>0.785398</upper>
          <effort>2</effort>
          <velocity>2</velocity>
        </limit>
        <dynamics>
          <damping>0.5</damping>
        </dynamics>
      </axis>
    </joint>
    <link name='hand_index_virtual_2_link'>
      <pose>0.11225 -0.954422 1.7385 -5.41487e-12 -0.523599 -1.5708</pose>
      <inertial>
        <pose>0.0065 0 0 0 -0 0</pose>
        <mass>0.01</mass>
        <inertia>
          <ixx>0.001</ixx>
          <ixy>0</ixy>
          <ixz>0</ixz>
          <iyy>0.001</iyy>
          <iyz>0</iyz>
          <izz>0.001</izz>
        </inertia>
      </inertial>
      <collision name='hand_index_virtual_2_link_collision'>
        <pose>0 0 0 0 -0 0</pose>
        <geometry>
          <box>
            <size>0.013 0.002 0.012</size>
          </box>
        </geometry>
        <surface>
          <contact>
            <ode/>
          </contact>
          <friction>
            <ode/>
          </friction>
        </surface>
      </collision>
      <visual name='hand_index_virtual_2_link_visual'>
        <pose>0.0065 0 0 0 -0 0</pose>
        <geometry>
          <box>
            <size>0.013 0.002 0.012</size>
          </box>
        </geometry>
        <material>
          <script>
            <name>Gazebo/Black</name>
            <uri>__default__</uri>
          </script>
        </material>
      </visual>
      <gravity>1</gravity>
      <velocity_decay>
        <linear>0</linear>
        <angular>0</angular>
      </velocity_decay>
      <self_collide>0</self_collide>
    </link>
    <joint name='hand_index_virtual_2_joint' type='revolute'>
      <child>hand_index_virtual_2_link</child>
      <parent>hand_index_flex_1_link</parent>
      <axis>
        <xyz>1.61279e-12 0.5 0.866025</xyz>
        <limit>
          <lower>0</lower>
          <upper>0.785398</upper>
          <effort>2</effort>
          <velocity>2</velocity>
        </limit>
        <dynamics>
          <damping>0.5</damping>
        </dynamics>
      </axis>
    </joint>
    <link name='hand_index_flex_2_link'>
      <pose>0.11225 -0.96568 1.745 -5.41487e-12 -0.523599 -1.5708</pose>
      <inertial>
        <pose>0.0047 0.0031 0 0 -0 0</pose>
        <mass>0.009</mass>
        <inertia>
          <ixx>0.001</ixx>
          <ixy>0</ixy>
          <ixz>0</ixz>
          <iyy>0.001</iyy>
          <iyz>0</iyz>
          <izz>0.001</izz>
        </inertia>
      </inertial>
      <collision name='hand_index_flex_2_link_collision'>
        <pose>0 0 0 0 -0 0</pose>
        <geometry>
          <mesh>
            <scale>1 1 1</scale>
            <uri>file://tiago/hey5_description/meshes/finger_flex_collision.stl</uri>
          </mesh>
        </geometry>
        <surface>
          <contact>
            <ode/>
          </contact>
          <friction>
            <ode/>
          </friction>
        </surface>
      </collision>
      <visual name='hand_index_flex_2_link_visual'>
        <pose>0 0 0 0 -0 0</pose>
        <geometry>
          <mesh>
            <scale>1 1 1</scale>
            <uri>file://tiago/hey5_description/meshes/finger_flex_collision.stl</uri>
          </mesh>
        </geometry>
        <material>
          <script>
            <name>Gazebo/Black</name>
            <uri>__default__</uri>
          </script>
        </material>
      </visual>
      <gravity>1</gravity>
      <velocity_decay>
        <linear>0</linear>
        <angular>0</angular>
      </velocity_decay>
      <self_collide>0</self_collide>
    </link>
    <joint name='hand_index_flex_2_joint' type='revolute'>
      <child>hand_index_flex_2_link</child>
      <parent>hand_index_virtual_2_link</parent>
      <axis>
        <xyz>1.61279e-12 0.5 0.866025</xyz>
        <limit>
          <lower>0</lower>
          <upper>0.785398</upper>
          <effort>2</effort>
          <velocity>2</velocity>
        </limit>
        <dynamics>
          <damping>0.5</damping>
        </dynamics>
      </axis>
    </joint>
    <link name='hand_index_virtual_3_link'>
      <pose>0.11225 -0.973474 1.7495 -5.41487e-12 -0.523599 -1.5708</pose>
      <inertial>
        <pose>0.0065 0 0 0 -0 0</pose>
        <mass>0.01</mass>
        <inertia>
          <ixx>0.001</ixx>
          <ixy>0</ixy>
          <ixz>0</ixz>
          <iyy>0.001</iyy>
          <iyz>0</iyz>
          <izz>0.001</izz>
        </inertia>
      </inertial>
      <collision name='hand_index_virtual_3_link_collision'>
        <pose>0 0 0 0 -0 0</pose>
        <geometry>
          <box>
            <size>0.013 0.002 0.012</size>
          </box>
        </geometry>
        <surface>
          <contact>
            <ode/>
          </contact>
          <friction>
            <ode/>
          </friction>
        </surface>
      </collision>
      <visual name='hand_index_virtual_3_link_visual'>
        <pose>0.0065 0 0 0 -0 0</pose>
        <geometry>
          <box>
            <size>0.013 0.002 0.012</size>
          </box>
        </geometry>
        <material>
          <script>
            <name>Gazebo/Black</name>
            <uri>__default__</uri>
          </script>
        </material>
      </visual>
      <gravity>1</gravity>
      <velocity_decay>
        <linear>0</linear>
        <angular>0</angular>
      </velocity_decay>
      <self_collide>0</self_collide>
    </link>
    <joint name='hand_index_virtual_3_joint' type='revolute'>
      <child>hand_index_virtual_3_link</child>
      <parent>hand_index_flex_2_link</parent>
      <axis>
        <xyz>1.61279e-12 0.5 0.866025</xyz>
        <limit>
          <lower>0</lower>
          <upper>0.785398</upper>
          <effort>2</effort>
          <velocity>2</velocity>
        </limit>
        <dynamics>
          <damping>0.5</damping>
        </dynamics>
      </axis>
    </joint>
    <link name='hand_index_flex_3_link'>
      <pose>0.11225 -0.984733 1.756 -5.41487e-12 -0.523599 -1.5708</pose>
      <inertial>
        <pose>0.0096 0.003 0 0 -0 0</pose>
        <mass>0.015</mass>
        <inertia>
          <ixx>0.001</ixx>
          <ixy>0</ixy>
          <ixz>0</ixz>
          <iyy>0.001</iyy>
          <iyz>0</iyz>
          <izz>0.001</izz>
        </inertia>
      </inertial>
      <collision name='hand_index_flex_3_link_collision'>
        <pose>0 0 0 0 -0 0</pose>
        <geometry>
          <mesh>
            <scale>1 1 1</scale>
            <uri>file://tiago/hey5_description/meshes/finger_flex_tip_collision.stl</uri>
          </mesh>
        </geometry>
        <surface>
          <contact>
            <ode/>
          </contact>
          <friction>
            <ode/>
          </friction>
        </surface>
      </collision>
      <visual name='hand_index_flex_3_link_visual'>
        <pose>0 0 0 0 -0 0</pose>
        <geometry>
          <mesh>
            <scale>1 1 1</scale>
            <uri>file://tiago/hey5_description/meshes/finger_flex_tip_collision.stl</uri>
          </mesh>
        </geometry>
        <material>
          <script>
            <name>Gazebo/Black</name>
            <uri>__default__</uri>
          </script>
        </material>
      </visual>
      <gravity>1</gravity>
      <velocity_decay>
        <linear>0</linear>
        <angular>0</angular>
      </velocity_decay>
      <self_collide>0</self_collide>
    </link>
    <joint name='hand_index_flex_3_joint' type='revolute'>
      <child>hand_index_flex_3_link</child>
      <parent>hand_index_virtual_3_link</parent>
      <axis>
        <xyz>1.61279e-12 0.5 0.866025</xyz>
        <limit>
          <lower>0</lower>
          <upper>0.785398</upper>
          <effort>2</effort>
          <velocity>2</velocity>
        </limit>
        <dynamics>
          <damping>0.5</damping>
        </dynamics>
      </axis>
    </joint>
    <link name='hand_index_link'>
      <pose>0.10805 -0.801075 1.6965 -4.68987e-12 4.8961e-12 -1.5708</pose>
      <inertial>
        <pose>0 0 0 0 -0 0</pose>
        <mass>0.05</mass>
        <inertia>
          <ixx>0.001</ixx>
          <ixy>0</ixy>
          <ixz>0</ixz>
          <iyy>0.001</iyy>
          <iyz>0</iyz>
          <izz>0.001</izz>
        </inertia>
      </inertial>
      <collision name='hand_index_link_collision'>
        <pose>0 0 0 0 -0 0</pose>
        <geometry>
          <sphere>
            <radius>0.001</radius>
          </sphere>
        </geometry>
      </collision>
      <visual name='hand_index_link_visual'>
        <pose>0 0 0 0 -0 0</pose>
        <geometry>
          <sphere>
            <radius>0.001</radius>
          </sphere>
        </geometry>
      </visual>
      <velocity_decay>
        <linear>0</linear>
        <angular>0</angular>
      </velocity_decay>
    </link>
    <joint name='hand_index_joint' type='revolute'>
      <child>hand_index_link</child>
      <parent>arm_7_link</parent>
      <axis>
        <xyz>4.68987e-12 -4.8961e-12 1</xyz>
        <limit>
          <lower>-3.05433</lower>
          <upper>6.80678</upper>
          <effort>2</effort>
          <velocity>3.35</velocity>
        </limit>
        <dynamics>
          <damping>0.5</damping>
        </dynamics>
      </axis>
    </joint>
    <link name='hand_little_abd_link'>
      <pose>0.11225 -0.917575 1.6645 -1.5708 0.523599 -1.5708</pose>
      <inertial>
        <pose>-0.0018 0 0.0028 0 -0 0</pose>
        <mass>0.018</mass>
        <inertia>
          <ixx>0.001</ixx>
          <ixy>0</ixy>
          <ixz>0</ixz>
          <iyy>0.001</iyy>
          <iyz>0</iyz>
          <izz>0.001</izz>
        </inertia>
      </inertial>
      <collision name='hand_little_abd_link_collision'>
        <pose>0 0 0 0 -0 0</pose>
        <geometry>
          <mesh>
            <scale>1 1 1</scale>
            <uri>file://tiago/hey5_description/meshes/finger_abd_collision.stl</uri>
          </mesh>
        </geometry>
        <surface>
          <contact>
            <ode/>
          </contact>
          <friction>
            <ode/>
          </friction>
        </surface>
      </collision>
      <visual name='hand_little_abd_link_visual'>
        <pose>0 0 0 0 -0 0</pose>
        <geometry>
          <mesh>
            <scale>1 1 1</scale>
            <uri>file://tiago/hey5_description/meshes/finger_abd_collision.stl</uri>
          </mesh>
        </geometry>
        <material>
          <script>
            <name>Gazebo/Black</name>
            <uri>__default__</uri>
          </script>
        </material>
      </visual>
      <gravity>1</gravity>
      <velocity_decay>
        <linear>0</linear>
        <angular>0</angular>
      </velocity_decay>
      <self_collide>0</self_collide>
    </link>
    <joint name='hand_little_abd_joint' type='revolute'>
      <child>hand_little_abd_link</child>
      <parent>arm_7_link</parent>
      <axis>
        <xyz>1 2.44843e-12 -4.48724e-13</xyz>
        <limit>
          <lower>-0.523599</lower>
          <upper>0.523599</upper>
          <effort>2</effort>
          <velocity>2</velocity>
        </limit>
        <dynamics>
          <damping>0.5</damping>
        </dynamics>
      </axis>
    </joint>
    <link name='hand_little_virtual_1_link'>
      <pose>0.11225 -0.925369 1.66 -5.41487e-12 0.523599 -1.5708</pose>
      <inertial>
        <pose>0.0065 0 0 0 -0 0</pose>
        <mass>0.01</mass>
        <inertia>
          <ixx>0.001</ixx>
          <ixy>0</ixy>
          <ixz>0</ixz>
          <iyy>0.001</iyy>
          <iyz>0</iyz>
          <izz>0.001</izz>
        </inertia>
      </inertial>
      <collision name='hand_little_virtual_1_link_collision'>
        <pose>0 0 0 0 -0 0</pose>
        <geometry>
          <box>
            <size>0.013 0.002 0.012</size>
          </box>
        </geometry>
        <surface>
          <contact>
            <ode/>
          </contact>
          <friction>
            <ode/>
          </friction>
        </surface>
      </collision>
      <visual name='hand_little_virtual_1_link_visual'>
        <pose>0.0065 0 0 0 -0 0</pose>
        <geometry>
          <box>
            <size>0.013 0.002 0.012</size>
          </box>
        </geometry>
        <material>
          <script>
            <name>Gazebo/Black</name>
            <uri>__default__</uri>
          </script>
        </material>
      </visual>
      <gravity>1</gravity>
      <velocity_decay>
        <linear>0</linear>
        <angular>0</angular>
      </velocity_decay>
      <self_collide>0</self_collide>
    </link>
    <joint name='hand_little_virtual_1_joint' type='revolute'>
      <child>hand_little_virtual_1_link</child>
      <parent>hand_little_abd_link</parent>
      <axis>
        <xyz>6.50957e-12 -0.5 0.866025</xyz>
        <limit>
          <lower>0</lower>
          <upper>0.785398</upper>
          <effort>2</effort>
          <velocity>2</velocity>
        </limit>
        <dynamics>
          <damping>0.5</damping>
        </dynamics>
      </axis>
    </joint>
    <link name='hand_little_flex_1_link'>
      <pose>0.11225 -0.936628 1.6535 -5.41487e-12 0.523599 -1.5708</pose>
      <inertial>
        <pose>0.0047 0.0031 0 0 -0 0</pose>
        <mass>0.009</mass>
        <inertia>
          <ixx>0.001</ixx>
          <ixy>0</ixy>
          <ixz>0</ixz>
          <iyy>0.001</iyy>
          <iyz>0</iyz>
          <izz>0.001</izz>
        </inertia>
      </inertial>
      <collision name='hand_little_flex_1_link_collision'>
        <pose>0 0 0 0 -0 0</pose>
        <geometry>
          <mesh>
            <scale>1 1 1</scale>
            <uri>file://tiago/hey5_description/meshes/finger_flex_collision.stl</uri>
          </mesh>
        </geometry>
        <surface>
          <contact>
            <ode/>
          </contact>
          <friction>
            <ode/>
          </friction>
        </surface>
      </collision>
      <visual name='hand_little_flex_1_link_visual'>
        <pose>0 0 0 0 -0 0</pose>
        <geometry>
          <mesh>
            <scale>1 1 1</scale>
            <uri>file://tiago/hey5_description/meshes/finger_flex_collision.stl</uri>
          </mesh>
        </geometry>
        <material>
          <script>
            <name>Gazebo/Black</name>
            <uri>__default__</uri>
          </script>
        </material>
      </visual>
      <gravity>1</gravity>
      <velocity_decay>
        <linear>0</linear>
        <angular>0</angular>
      </velocity_decay>
      <self_collide>0</self_collide>
    </link>
    <joint name='hand_little_flex_1_joint' type='revolute'>
      <child>hand_little_flex_1_link</child>
      <parent>hand_little_virtual_1_link</parent>
      <axis>
        <xyz>6.50957e-12 -0.5 0.866025</xyz>
        <limit>
          <lower>0</lower>
          <upper>0.785398</upper>
          <effort>2</effort>
          <velocity>2</velocity>
        </limit>
        <dynamics>
          <damping>0.5</damping>
        </dynamics>
      </axis>
    </joint>
    <link name='hand_little_virtual_2_link'>
      <pose>0.11225 -0.944422 1.649 -5.41487e-12 0.523599 -1.5708</pose>
      <inertial>
        <pose>0.0065 0 0 0 -0 0</pose>
        <mass>0.01</mass>
        <inertia>
          <ixx>0.001</ixx>
          <ixy>0</ixy>
          <ixz>0</ixz>
          <iyy>0.001</iyy>
          <iyz>0</iyz>
          <izz>0.001</izz>
        </inertia>
      </inertial>
      <collision name='hand_little_virtual_2_link_collision'>
        <pose>0 0 0 0 -0 0</pose>
        <geometry>
          <box>
            <size>0.013 0.002 0.012</size>
          </box>
        </geometry>
        <surface>
          <contact>
            <ode/>
          </contact>
          <friction>
            <ode/>
          </friction>
        </surface>
      </collision>
      <visual name='hand_little_virtual_2_link_visual'>
        <pose>0.0065 0 0 0 -0 0</pose>
        <geometry>
          <box>
            <size>0.013 0.002 0.012</size>
          </box>
        </geometry>
        <material>
          <script>
            <name>Gazebo/Black</name>
            <uri>__default__</uri>
          </script>
        </material>
      </visual>
      <gravity>1</gravity>
      <velocity_decay>
        <linear>0</linear>
        <angular>0</angular>
      </velocity_decay>
      <self_collide>0</self_collide>
    </link>
    <joint name='hand_little_virtual_2_joint' type='revolute'>
      <child>hand_little_virtual_2_link</child>
      <parent>hand_little_flex_1_link</parent>
      <axis>
        <xyz>6.50957e-12 -0.5 0.866025</xyz>
        <limit>
          <lower>0</lower>
          <upper>0.785398</upper>
          <effort>2</effort>
          <velocity>2</velocity>
        </limit>
        <dynamics>
          <damping>0.5</damping>
        </dynamics>
      </axis>
    </joint>
    <link name='hand_little_flex_2_link'>
      <pose>0.11225 -0.95568 1.6425 -5.41487e-12 0.523599 -1.5708</pose>
      <inertial>
        <pose>0.0047 0.0031 0 0 -0 0</pose>
        <mass>0.009</mass>
        <inertia>
          <ixx>0.001</ixx>
          <ixy>0</ixy>
          <ixz>0</ixz>
          <iyy>0.001</iyy>
          <iyz>0</iyz>
          <izz>0.001</izz>
        </inertia>
      </inertial>
      <collision name='hand_little_flex_2_link_collision'>
        <pose>0 0 0 0 -0 0</pose>
        <geometry>
          <mesh>
            <scale>1 1 1</scale>
            <uri>file://tiago/hey5_description/meshes/finger_flex_collision.stl</uri>
          </mesh>
        </geometry>
        <surface>
          <contact>
            <ode/>
          </contact>
          <friction>
            <ode/>
          </friction>
        </surface>
      </collision>
      <visual name='hand_little_flex_2_link_visual'>
        <pose>0 0 0 0 -0 0</pose>
        <geometry>
          <mesh>
            <scale>1 1 1</scale>
            <uri>file://tiago/hey5_description/meshes/finger_flex_collision.stl</uri>
          </mesh>
        </geometry>
        <material>
          <script>
            <name>Gazebo/Black</name>
            <uri>__default__</uri>
          </script>
        </material>
      </visual>
      <gravity>1</gravity>
      <velocity_decay>
        <linear>0</linear>
        <angular>0</angular>
      </velocity_decay>
      <self_collide>0</self_collide>
    </link>
    <joint name='hand_little_flex_2_joint' type='revolute'>
      <child>hand_little_flex_2_link</child>
      <parent>hand_little_virtual_2_link</parent>
      <axis>
        <xyz>6.50957e-12 -0.5 0.866025</xyz>
        <limit>
          <lower>0</lower>
          <upper>0.785398</upper>
          <effort>2</effort>
          <velocity>2</velocity>
        </limit>
        <dynamics>
          <damping>0.5</damping>
        </dynamics>
      </axis>
    </joint>
    <link name='hand_little_virtual_3_link'>
      <pose>0.11225 -0.963474 1.638 -5.41487e-12 0.523599 -1.5708</pose>
      <inertial>
        <pose>0.0065 0 0 0 -0 0</pose>
        <mass>0.01</mass>
        <inertia>
          <ixx>0.001</ixx>
          <ixy>0</ixy>
          <ixz>0</ixz>
          <iyy>0.001</iyy>
          <iyz>0</iyz>
          <izz>0.001</izz>
        </inertia>
      </inertial>
      <collision name='hand_little_virtual_3_link_collision'>
        <pose>0 0 0 0 -0 0</pose>
        <geometry>
          <box>
            <size>0.013 0.002 0.012</size>
          </box>
        </geometry>
        <surface>
          <contact>
            <ode/>
          </contact>
          <friction>
            <ode/>
          </friction>
        </surface>
      </collision>
      <visual name='hand_little_virtual_3_link_visual'>
        <pose>0.0065 0 0 0 -0 0</pose>
        <geometry>
          <box>
            <size>0.013 0.002 0.012</size>
          </box>
        </geometry>
        <material>
          <script>
            <name>Gazebo/Black</name>
            <uri>__default__</uri>
          </script>
        </material>
      </visual>
      <gravity>1</gravity>
      <velocity_decay>
        <linear>0</linear>
        <angular>0</angular>
      </velocity_decay>
      <self_collide>0</self_collide>
    </link>
    <joint name='hand_little_virtual_3_joint' type='revolute'>
      <child>hand_little_virtual_3_link</child>
      <parent>hand_little_flex_2_link</parent>
      <axis>
        <xyz>6.50957e-12 -0.5 0.866025</xyz>
        <limit>
          <lower>0</lower>
          <upper>0.785398</upper>
          <effort>2</effort>
          <velocity>2</velocity>
        </limit>
        <dynamics>
          <damping>0.5</damping>
        </dynamics>
      </axis>
    </joint>
    <link name='hand_little_flex_3_link'>
      <pose>0.11225 -0.974733 1.6315 -5.41487e-12 0.523599 -1.5708</pose>
      <inertial>
        <pose>0.0096 0.003 0 0 -0 0</pose>
        <mass>0.015</mass>
        <inertia>
          <ixx>0.001</ixx>
          <ixy>0</ixy>
          <ixz>0</ixz>
          <iyy>0.001</iyy>
          <iyz>0</iyz>
          <izz>0.001</izz>
        </inertia>
      </inertial>
      <collision name='hand_little_flex_3_link_collision'>
        <pose>0 0 0 0 -0 0</pose>
        <geometry>
          <mesh>
            <scale>1 1 1</scale>
            <uri>file://tiago/hey5_description/meshes/finger_flex_tip_collision.stl</uri>
          </mesh>
        </geometry>
        <surface>
          <contact>
            <ode/>
          </contact>
          <friction>
            <ode/>
          </friction>
        </surface>
      </collision>
      <visual name='hand_little_flex_3_link_visual'>
        <pose>0 0 0 0 -0 0</pose>
        <geometry>
          <mesh>
            <scale>1 1 1</scale>
            <uri>file://tiago/hey5_description/meshes/finger_flex_tip_collision.stl</uri>
          </mesh>
        </geometry>
        <material>
          <script>
            <name>Gazebo/Black</name>
            <uri>__default__</uri>
          </script>
        </material>
      </visual>
      <gravity>1</gravity>
      <velocity_decay>
        <linear>0</linear>
        <angular>0</angular>
      </velocity_decay>
      <self_collide>0</self_collide>
    </link>
    <joint name='hand_little_flex_3_joint' type='revolute'>
      <child>hand_little_flex_3_link</child>
      <parent>hand_little_virtual_3_link</parent>
      <axis>
        <xyz>6.50957e-12 -0.5 0.866025</xyz>
        <limit>
          <lower>0</lower>
          <upper>0.785398</upper>
          <effort>2</effort>
          <velocity>2</velocity>
        </limit>
        <dynamics>
          <damping>0.5</damping>
        </dynamics>
      </axis>
    </joint>
    <link name='hand_middle_abd_link'>
      <pose>0.11225 -0.934575 1.7035 -1.5708 4.89608e-12 -1.5708</pose>
      <inertial>
        <pose>-0.0018 0 0.0028 0 -0 0</pose>
        <mass>0.018</mass>
        <inertia>
          <ixx>0.001</ixx>
          <ixy>0</ixy>
          <ixz>0</ixz>
          <iyy>0.001</iyy>
          <iyz>0</iyz>
          <izz>0.001</izz>
        </inertia>
      </inertial>
      <collision name='hand_middle_abd_link_collision'>
        <pose>0 0 0 0 -0 0</pose>
        <geometry>
          <mesh>
            <scale>1 1 1</scale>
            <uri>file://tiago/hey5_description/meshes/finger_abd_collision.stl</uri>
          </mesh>
        </geometry>
        <surface>
          <contact>
            <ode/>
          </contact>
          <friction>
            <ode/>
          </friction>
        </surface>
      </collision>
      <visual name='hand_middle_abd_link_visual'>
        <pose>0 0 0 0 -0 0</pose>
        <geometry>
          <mesh>
            <scale>1 1 1</scale>
            <uri>file://tiago/hey5_description/meshes/finger_abd_collision.stl</uri>
          </mesh>
        </geometry>
        <material>
          <script>
            <name>Gazebo/Black</name>
            <uri>__default__</uri>
          </script>
        </material>
      </visual>
      <gravity>1</gravity>
      <velocity_decay>
        <linear>0</linear>
        <angular>0</angular>
      </velocity_decay>
      <self_collide>0</self_collide>
    </link>
    <joint name='hand_middle_abd_joint' type='revolute'>
      <child>hand_middle_abd_link</child>
      <parent>arm_7_link</parent>
      <axis>
        <xyz>1 4.89675e-12 2.07057e-13</xyz>
        <limit>
          <lower>-0.523599</lower>
          <upper>0.523599</upper>
          <effort>2</effort>
          <velocity>2</velocity>
        </limit>
        <dynamics>
          <damping>0.5</damping>
        </dynamics>
      </axis>
    </joint>
    <link name='hand_middle_virtual_1_link'>
      <pose>0.11225 -0.943575 1.7035 -4.68963e-12 4.89625e-12 -1.5708</pose>
      <inertial>
        <pose>0.0065 0 0 0 -0 0</pose>
        <mass>0.01</mass>
        <inertia>
          <ixx>0.001</ixx>
          <ixy>0</ixy>
          <ixz>0</ixz>
          <iyy>0.001</iyy>
          <iyz>0</iyz>
          <izz>0.001</izz>
        </inertia>
      </inertial>
      <collision name='hand_middle_virtual_1_link_collision'>
        <pose>0 0 0 0 -0 0</pose>
        <geometry>
          <box>
            <size>0.013 0.002 0.012</size>
          </box>
        </geometry>
        <surface>
          <contact>
            <ode/>
          </contact>
          <friction>
            <ode/>
          </friction>
        </surface>
      </collision>
      <visual name='hand_middle_virtual_1_link_visual'>
        <pose>0.0065 0 0 0 -0 0</pose>
        <geometry>
          <box>
            <size>0.013 0.002 0.012</size>
          </box>
        </geometry>
        <material>
          <script>
            <name>Gazebo/Black</name>
            <uri>__default__</uri>
          </script>
        </material>
      </visual>
      <gravity>1</gravity>
      <velocity_decay>
        <linear>0</linear>
        <angular>0</angular>
      </velocity_decay>
      <self_collide>0</self_collide>
    </link>
    <joint name='hand_middle_virtual_1_joint' type='revolute'>
      <child>hand_middle_virtual_1_link</child>
      <parent>hand_middle_abd_link</parent>
      <axis>
        <xyz>4.68963e-12 -4.89625e-12 1</xyz>
        <limit>
          <lower>0</lower>
          <upper>0.785398</upper>
          <effort>2</effort>
          <velocity>2</velocity>
        </limit>
        <dynamics>
          <damping>0.5</damping>
        </dynamics>
      </axis>
    </joint>
    <link name='hand_middle_flex_1_link'>
      <pose>0.11225 -0.956575 1.7035 -4.68963e-12 4.89625e-12 -1.5708</pose>
      <inertial>
        <pose>0.0047 0.0031 0 0 -0 0</pose>
        <mass>0.009</mass>
        <inertia>
          <ixx>0.001</ixx>
          <ixy>0</ixy>
          <ixz>0</ixz>
          <iyy>0.001</iyy>
          <iyz>0</iyz>
          <izz>0.001</izz>
        </inertia>
      </inertial>
      <collision name='hand_middle_flex_1_link_collision'>
        <pose>0 0 0 0 -0 0</pose>
        <geometry>
          <mesh>
            <scale>1 1 1</scale>
            <uri>file://tiago/hey5_description/meshes/finger_flex_collision.stl</uri>
          </mesh>
        </geometry>
        <surface>
          <contact>
            <ode/>
          </contact>
          <friction>
            <ode/>
          </friction>
        </surface>
      </collision>
      <visual name='hand_middle_flex_1_link_visual'>
        <pose>0 0 0 0 -0 0</pose>
        <geometry>
          <mesh>
            <scale>1 1 1</scale>
            <uri>file://tiago/hey5_description/meshes/finger_flex_collision.stl</uri>
          </mesh>
        </geometry>
        <material>
          <script>
            <name>Gazebo/Black</name>
            <uri>__default__</uri>
          </script>
        </material>
      </visual>
      <gravity>1</gravity>
      <velocity_decay>
        <linear>0</linear>
        <angular>0</angular>
      </velocity_decay>
      <self_collide>0</self_collide>
    </link>
    <joint name='hand_middle_flex_1_joint' type='revolute'>
      <child>hand_middle_flex_1_link</child>
      <parent>hand_middle_virtual_1_link</parent>
      <axis>
        <xyz>4.68963e-12 -4.89625e-12 1</xyz>
        <limit>
          <lower>0</lower>
          <upper>0.785398</upper>
          <effort>2</effort>
          <velocity>2</velocity>
        </limit>
        <dynamics>
          <damping>0.5</damping>
        </dynamics>
      </axis>
    </joint>
    <link name='hand_middle_virtual_2_link'>
      <pose>0.11225 -0.965575 1.7035 -4.68963e-12 4.89625e-12 -1.5708</pose>
      <inertial>
        <pose>0.0065 0 0 0 -0 0</pose>
        <mass>0.01</mass>
        <inertia>
          <ixx>0.001</ixx>
          <ixy>0</ixy>
          <ixz>0</ixz>
          <iyy>0.001</iyy>
          <iyz>0</iyz>
          <izz>0.001</izz>
        </inertia>
      </inertial>
      <collision name='hand_middle_virtual_2_link_collision'>
        <pose>0 0 0 0 -0 0</pose>
        <geometry>
          <box>
            <size>0.013 0.002 0.012</size>
          </box>
        </geometry>
        <surface>
          <contact>
            <ode/>
          </contact>
          <friction>
            <ode/>
          </friction>
        </surface>
      </collision>
      <visual name='hand_middle_virtual_2_link_visual'>
        <pose>0.0065 0 0 0 -0 0</pose>
        <geometry>
          <box>
            <size>0.013 0.002 0.012</size>
          </box>
        </geometry>
        <material>
          <script>
            <name>Gazebo/Black</name>
            <uri>__default__</uri>
          </script>
        </material>
      </visual>
      <gravity>1</gravity>
      <velocity_decay>
        <linear>0</linear>
        <angular>0</angular>
      </velocity_decay>
      <self_collide>0</self_collide>
    </link>
    <joint name='hand_middle_virtual_2_joint' type='revolute'>
      <child>hand_middle_virtual_2_link</child>
      <parent>hand_middle_flex_1_link</parent>
      <axis>
        <xyz>4.68963e-12 -4.89625e-12 1</xyz>
        <limit>
          <lower>0</lower>
          <upper>0.785398</upper>
          <effort>2</effort>
          <velocity>2</velocity>
        </limit>
        <dynamics>
          <damping>0.5</damping>
        </dynamics>
      </axis>
    </joint>
    <link name='hand_middle_flex_2_link'>
      <pose>0.11225 -0.978575 1.7035 -4.68963e-12 4.89625e-12 -1.5708</pose>
      <inertial>
        <pose>0.0047 0.0031 0 0 -0 0</pose>
        <mass>0.009</mass>
        <inertia>
          <ixx>0.001</ixx>
          <ixy>0</ixy>
          <ixz>0</ixz>
          <iyy>0.001</iyy>
          <iyz>0</iyz>
          <izz>0.001</izz>
        </inertia>
      </inertial>
      <collision name='hand_middle_flex_2_link_collision'>
        <pose>0 0 0 0 -0 0</pose>
        <geometry>
          <mesh>
            <scale>1 1 1</scale>
            <uri>file://tiago/hey5_description/meshes/finger_flex_collision.stl</uri>
          </mesh>
        </geometry>
        <surface>
          <contact>
            <ode/>
          </contact>
          <friction>
            <ode/>
          </friction>
        </surface>
      </collision>
      <visual name='hand_middle_flex_2_link_visual'>
        <pose>0 0 0 0 -0 0</pose>
        <geometry>
          <mesh>
            <scale>1 1 1</scale>
            <uri>file://tiago/hey5_description/meshes/finger_flex_collision.stl</uri>
          </mesh>
        </geometry>
        <material>
          <script>
            <name>Gazebo/Black</name>
            <uri>__default__</uri>
          </script>
        </material>
      </visual>
      <gravity>1</gravity>
      <velocity_decay>
        <linear>0</linear>
        <angular>0</angular>
      </velocity_decay>
      <self_collide>0</self_collide>
    </link>
    <joint name='hand_middle_flex_2_joint' type='revolute'>
      <child>hand_middle_flex_2_link</child>
      <parent>hand_middle_virtual_2_link</parent>
      <axis>
        <xyz>4.68963e-12 -4.89625e-12 1</xyz>
        <limit>
          <lower>0</lower>
          <upper>0.785398</upper>
          <effort>2</effort>
          <velocity>2</velocity>
        </limit>
        <dynamics>
          <damping>0.5</damping>
        </dynamics>
      </axis>
    </joint>
    <link name='hand_middle_virtual_3_link'>
      <pose>0.11225 -0.987575 1.7035 -4.68963e-12 4.89625e-12 -1.5708</pose>
      <inertial>
        <pose>0.0065 0 0 0 -0 0</pose>
        <mass>0.01</mass>
        <inertia>
          <ixx>0.001</ixx>
          <ixy>0</ixy>
          <ixz>0</ixz>
          <iyy>0.001</iyy>
          <iyz>0</iyz>
          <izz>0.001</izz>
        </inertia>
      </inertial>
      <collision name='hand_middle_virtual_3_link_collision'>
        <pose>0 0 0 0 -0 0</pose>
        <geometry>
          <box>
            <size>0.013 0.002 0.012</size>
          </box>
        </geometry>
        <surface>
          <contact>
            <ode/>
          </contact>
          <friction>
            <ode/>
          </friction>
        </surface>
      </collision>
      <visual name='hand_middle_virtual_3_link_visual'>
        <pose>0.0065 0 0 0 -0 0</pose>
        <geometry>
          <box>
            <size>0.013 0.002 0.012</size>
          </box>
        </geometry>
        <material>
          <script>
            <name>Gazebo/Black</name>
            <uri>__default__</uri>
          </script>
        </material>
      </visual>
      <gravity>1</gravity>
      <velocity_decay>
        <linear>0</linear>
        <angular>0</angular>
      </velocity_decay>
      <self_collide>0</self_collide>
    </link>
    <joint name='hand_middle_virtual_3_joint' type='revolute'>
      <child>hand_middle_virtual_3_link</child>
      <parent>hand_middle_flex_2_link</parent>
      <axis>
        <xyz>4.68963e-12 -4.89625e-12 1</xyz>
        <limit>
          <lower>0</lower>
          <upper>0.785398</upper>
          <effort>2</effort>
          <velocity>2</velocity>
        </limit>
        <dynamics>
          <damping>0.5</damping>
        </dynamics>
      </axis>
    </joint>
    <link name='hand_middle_flex_3_link'>
      <pose>0.11225 -1.00058 1.7035 -4.68963e-12 4.89625e-12 -1.5708</pose>
      <inertial>
        <pose>0.0096 0.003 0 0 -0 0</pose>
        <mass>0.015</mass>
        <inertia>
          <ixx>0.001</ixx>
          <ixy>0</ixy>
          <ixz>0</ixz>
          <iyy>0.001</iyy>
          <iyz>0</iyz>
          <izz>0.001</izz>
        </inertia>
      </inertial>
      <collision name='hand_middle_flex_3_link_collision'>
        <pose>0 0 0 0 -0 0</pose>
        <geometry>
          <mesh>
            <scale>1 1 1</scale>
            <uri>file://tiago/hey5_description/meshes/finger_flex_tip_collision.stl</uri>
          </mesh>
        </geometry>
        <surface>
          <contact>
            <ode/>
          </contact>
          <friction>
            <ode/>
          </friction>
        </surface>
      </collision>
      <visual name='hand_middle_flex_3_link_visual'>
        <pose>0 0 0 0 -0 0</pose>
        <geometry>
          <mesh>
            <scale>1 1 1</scale>
            <uri>file://tiago/hey5_description/meshes/finger_flex_tip_collision.stl</uri>
          </mesh>
        </geometry>
        <material>
          <script>
            <name>Gazebo/Black</name>
            <uri>__default__</uri>
          </script>
        </material>
      </visual>
      <gravity>1</gravity>
      <velocity_decay>
        <linear>0</linear>
        <angular>0</angular>
      </velocity_decay>
      <self_collide>0</self_collide>
    </link>
    <joint name='hand_middle_flex_3_joint' type='revolute'>
      <child>hand_middle_flex_3_link</child>
      <parent>hand_middle_virtual_3_link</parent>
      <axis>
        <xyz>4.68963e-12 -4.89625e-12 1</xyz>
        <limit>
          <lower>0</lower>
          <upper>0.785398</upper>
          <effort>2</effort>
          <velocity>2</velocity>
        </limit>
        <dynamics>
          <damping>0.5</damping>
        </dynamics>
      </axis>
    </joint>
    <link name='hand_mrl_link'>
      <pose>0.10805 -0.801075 1.6965 -4.68987e-12 4.8961e-12 -1.5708</pose>
      <inertial>
        <pose>0 0 0 0 -0 0</pose>
        <mass>0.05</mass>
        <inertia>
          <ixx>0.001</ixx>
          <ixy>0</ixy>
          <ixz>0</ixz>
          <iyy>0.001</iyy>
          <iyz>0</iyz>
          <izz>0.001</izz>
        </inertia>
      </inertial>
      <collision name='hand_mrl_link_collision'>
        <pose>0 0 0 0 -0 0</pose>
        <geometry>
          <sphere>
            <radius>0.001</radius>
          </sphere>
        </geometry>
      </collision>
      <visual name='hand_mrl_link_visual'>
        <pose>0 0 0 0 -0 0</pose>
        <geometry>
          <sphere>
            <radius>0.001</radius>
          </sphere>
        </geometry>
      </visual>
      <velocity_decay>
        <linear>0</linear>
        <angular>0</angular>
      </velocity_decay>
    </link>
    <joint name='hand_mrl_joint' type='revolute'>
      <child>hand_mrl_link</child>
      <parent>arm_7_link</parent>
      <axis>
        <xyz>4.68987e-12 -4.8961e-12 1</xyz>
        <limit>
          <lower>-2.53073</lower>
          <upper>9.25025</upper>
          <effort>2</effort>
          <velocity>3.56</velocity>
        </limit>
        <dynamics>
          <damping>0.5</damping>
        </dynamics>
      </axis>
    </joint>
    <link name='hand_ring_abd_link'>
      <pose>0.11225 -0.927575 1.684 -1.5708 0.261799 -1.5708</pose>
      <inertial>
        <pose>-0.0018 0 0.0028 0 -0 0</pose>
        <mass>0.018</mass>
        <inertia>
          <ixx>0.001</ixx>
          <ixy>0</ixy>
          <ixz>0</ixz>
          <iyy>0.001</iyy>
          <iyz>0</iyz>
          <izz>0.001</izz>
        </inertia>
      </inertial>
      <collision name='hand_ring_abd_link_collision'>
        <pose>0 0 0 0 -0 0</pose>
        <geometry>
          <mesh>
            <scale>1 1 1</scale>
            <uri>file://tiago/hey5_description/meshes/finger_abd_collision.stl</uri>
          </mesh>
        </geometry>
        <surface>
          <contact>
            <ode/>
          </contact>
          <friction>
            <ode/>
          </friction>
        </surface>
      </collision>
      <visual name='hand_ring_abd_link_visual'>
        <pose>0 0 0 0 -0 0</pose>
        <geometry>
          <mesh>
            <scale>1 1 1</scale>
            <uri>file://tiago/hey5_description/meshes/finger_abd_collision.stl</uri>
          </mesh>
        </geometry>
        <material>
          <script>
            <name>Gazebo/Black</name>
            <uri>__default__</uri>
          </script>
        </material>
      </visual>
      <gravity>1</gravity>
      <velocity_decay>
        <linear>0</linear>
        <angular>0</angular>
      </velocity_decay>
      <self_collide>0</self_collide>
    </link>
    <joint name='hand_ring_abd_joint' type='revolute'>
      <child>hand_ring_abd_link</child>
      <parent>arm_7_link</parent>
      <axis>
        <xyz>1 3.62912e-12 4.01623e-14</xyz>
        <limit>
          <lower>-0.523599</lower>
          <upper>0.523599</upper>
          <effort>2</effort>
          <velocity>2</velocity>
        </limit>
        <dynamics>
          <damping>0.5</damping>
        </dynamics>
      </axis>
    </joint>
    <link name='hand_ring_virtual_1_link'>
      <pose>0.11225 -0.936268 1.681671 -4.85507e-12 0.261799 -1.5708</pose>
      <inertial>
        <pose>0.0065 0 0 0 -0 0</pose>
        <mass>0.01</mass>
        <inertia>
          <ixx>0.001</ixx>
          <ixy>0</ixy>
          <ixz>0</ixz>
          <iyy>0.001</iyy>
          <iyz>0</iyz>
          <izz>0.001</izz>
        </inertia>
      </inertial>
      <collision name='hand_ring_virtual_1_link_collision'>
        <pose>0 0 0 0 -0 0</pose>
        <geometry>
          <box>
            <size>0.013 0.002 0.012</size>
          </box>
        </geometry>
        <surface>
          <contact>
            <ode/>
          </contact>
          <friction>
            <ode/>
          </friction>
        </surface>
      </collision>
      <visual name='hand_ring_virtual_1_link_visual'>
        <pose>0.0065 0 0 0 -0 0</pose>
        <geometry>
          <box>
            <size>0.013 0.002 0.012</size>
          </box>
        </geometry>
        <material>
          <script>
            <name>Gazebo/Black</name>
            <uri>__default__</uri>
          </script>
        </material>
      </visual>
      <gravity>1</gravity>
      <velocity_decay>
        <linear>0</linear>
        <angular>0</angular>
      </velocity_decay>
      <self_collide>0</self_collide>
    </link>
    <joint name='hand_ring_virtual_1_joint' type='revolute'>
      <child>hand_ring_virtual_1_link</child>
      <parent>hand_ring_abd_link</parent>
      <axis>
        <xyz>5.79713e-12 -0.258819 0.965926</xyz>
        <limit>
          <lower>0</lower>
          <upper>0.785398</upper>
          <effort>2</effort>
          <velocity>2</velocity>
        </limit>
        <dynamics>
          <damping>0.5</damping>
        </dynamics>
      </axis>
    </joint>
    <link name='hand_ring_flex_1_link'>
      <pose>0.11225 -0.948825 1.678306 -4.85507e-12 0.261799 -1.5708</pose>
      <inertial>
        <pose>0.0047 0.0031 0 0 -0 0</pose>
        <mass>0.009</mass>
        <inertia>
          <ixx>0.001</ixx>
          <ixy>0</ixy>
          <ixz>0</ixz>
          <iyy>0.001</iyy>
          <iyz>0</iyz>
          <izz>0.001</izz>
        </inertia>
      </inertial>
      <collision name='hand_ring_flex_1_link_collision'>
        <pose>0 0 0 0 -0 0</pose>
        <geometry>
          <mesh>
            <scale>1 1 1</scale>
            <uri>file://tiago/hey5_description/meshes/finger_flex_collision.stl</uri>
          </mesh>
        </geometry>
        <surface>
          <contact>
            <ode/>
          </contact>
          <friction>
            <ode/>
          </friction>
        </surface>
      </collision>
      <visual name='hand_ring_flex_1_link_visual'>
        <pose>0 0 0 0 -0 0</pose>
        <geometry>
          <mesh>
            <scale>1 1 1</scale>
            <uri>file://tiago/hey5_description/meshes/finger_flex_collision.stl</uri>
          </mesh>
        </geometry>
        <material>
          <script>
            <name>Gazebo/Black</name>
            <uri>__default__</uri>
          </script>
        </material>
      </visual>
      <gravity>1</gravity>
      <velocity_decay>
        <linear>0</linear>
        <angular>0</angular>
      </velocity_decay>
      <self_collide>0</self_collide>
    </link>
    <joint name='hand_ring_flex_1_joint' type='revolute'>
      <child>hand_ring_flex_1_link</child>
      <parent>hand_ring_virtual_1_link</parent>
      <axis>
        <xyz>5.79713e-12 -0.258819 0.965926</xyz>
        <limit>
          <lower>0</lower>
          <upper>0.785398</upper>
          <effort>2</effort>
          <velocity>2</velocity>
        </limit>
        <dynamics>
          <damping>0.5</damping>
        </dynamics>
      </axis>
    </joint>
    <link name='hand_ring_virtual_2_link'>
      <pose>0.11225 -0.957519 1.675977 -4.85507e-12 0.261799 -1.5708</pose>
      <inertial>
        <pose>0.0065 0 0 0 -0 0</pose>
        <mass>0.01</mass>
        <inertia>
          <ixx>0.001</ixx>
          <ixy>0</ixy>
          <ixz>0</ixz>
          <iyy>0.001</iyy>
          <iyz>0</iyz>
          <izz>0.001</izz>
        </inertia>
      </inertial>
      <collision name='hand_ring_virtual_2_link_collision'>
        <pose>0 0 0 0 -0 0</pose>
        <geometry>
          <box>
            <size>0.013 0.002 0.012</size>
          </box>
        </geometry>
        <surface>
          <contact>
            <ode/>
          </contact>
          <friction>
            <ode/>
          </friction>
        </surface>
      </collision>
      <visual name='hand_ring_virtual_2_link_visual'>
        <pose>0.0065 0 0 0 -0 0</pose>
        <geometry>
          <box>
            <size>0.013 0.002 0.012</size>
          </box>
        </geometry>
        <material>
          <script>
            <name>Gazebo/Black</name>
            <uri>__default__</uri>
          </script>
        </material>
      </visual>
      <gravity>1</gravity>
      <velocity_decay>
        <linear>0</linear>
        <angular>0</angular>
      </velocity_decay>
      <self_collide>0</self_collide>
    </link>
    <joint name='hand_ring_virtual_2_joint' type='revolute'>
      <child>hand_ring_virtual_2_link</child>
      <parent>hand_ring_flex_1_link</parent>
      <axis>
        <xyz>5.79713e-12 -0.258819 0.965926</xyz>
        <limit>
          <lower>0</lower>
          <upper>0.785398</upper>
          <effort>2</effort>
          <velocity>2</velocity>
        </limit>
        <dynamics>
          <damping>0.5</damping>
        </dynamics>
      </axis>
    </joint>
    <link name='hand_ring_flex_2_link'>
      <pose>0.11225 -0.970076 1.672612 -4.85507e-12 0.261799 -1.5708</pose>
      <inertial>
        <pose>0.0047 0.0031 0 0 -0 0</pose>
        <mass>0.009</mass>
        <inertia>
          <ixx>0.001</ixx>
          <ixy>0</ixy>
          <ixz>0</ixz>
          <iyy>0.001</iyy>
          <iyz>0</iyz>
          <izz>0.001</izz>
        </inertia>
      </inertial>
      <collision name='hand_ring_flex_2_link_collision'>
        <pose>0 0 0 0 -0 0</pose>
        <geometry>
          <mesh>
            <scale>1 1 1</scale>
            <uri>file://tiago/hey5_description/meshes/finger_flex_collision.stl</uri>
          </mesh>
        </geometry>
        <surface>
          <contact>
            <ode/>
          </contact>
          <friction>
            <ode/>
          </friction>
        </surface>
      </collision>
      <visual name='hand_ring_flex_2_link_visual'>
        <pose>0 0 0 0 -0 0</pose>
        <geometry>
          <mesh>
            <scale>1 1 1</scale>
            <uri>file://tiago/hey5_description/meshes/finger_flex_collision.stl</uri>
          </mesh>
        </geometry>
        <material>
          <script>
            <name>Gazebo/Black</name>
            <uri>__default__</uri>
          </script>
        </material>
      </visual>
      <gravity>1</gravity>
      <velocity_decay>
        <linear>0</linear>
        <angular>0</angular>
      </velocity_decay>
      <self_collide>0</self_collide>
    </link>
    <joint name='hand_ring_flex_2_joint' type='revolute'>
      <child>hand_ring_flex_2_link</child>
      <parent>hand_ring_virtual_2_link</parent>
      <axis>
        <xyz>5.79713e-12 -0.258819 0.965926</xyz>
        <limit>
          <lower>0</lower>
          <upper>0.785398</upper>
          <effort>2</effort>
          <velocity>2</velocity>
        </limit>
        <dynamics>
          <damping>0.5</damping>
        </dynamics>
      </axis>
    </joint>
    <link name='hand_ring_virtual_3_link'>
      <pose>0.11225 -0.978769 1.670283 -4.85507e-12 0.261799 -1.5708</pose>
      <inertial>
        <pose>0.0065 0 0 0 -0 0</pose>
        <mass>0.01</mass>
        <inertia>
          <ixx>0.001</ixx>
          <ixy>0</ixy>
          <ixz>0</ixz>
          <iyy>0.001</iyy>
          <iyz>0</iyz>
          <izz>0.001</izz>
        </inertia>
      </inertial>
      <collision name='hand_ring_virtual_3_link_collision'>
        <pose>0 0 0 0 -0 0</pose>
        <geometry>
          <box>
            <size>0.013 0.002 0.012</size>
          </box>
        </geometry>
        <surface>
          <contact>
            <ode/>
          </contact>
          <friction>
            <ode/>
          </friction>
        </surface>
      </collision>
      <visual name='hand_ring_virtual_3_link_visual'>
        <pose>0.0065 0 0 0 -0 0</pose>
        <geometry>
          <box>
            <size>0.013 0.002 0.012</size>
          </box>
        </geometry>
        <material>
          <script>
            <name>Gazebo/Black</name>
            <uri>__default__</uri>
          </script>
        </material>
      </visual>
      <gravity>1</gravity>
      <velocity_decay>
        <linear>0</linear>
        <angular>0</angular>
      </velocity_decay>
      <self_collide>0</self_collide>
    </link>
    <joint name='hand_ring_virtual_3_joint' type='revolute'>
      <child>hand_ring_virtual_3_link</child>
      <parent>hand_ring_flex_2_link</parent>
      <axis>
        <xyz>5.79713e-12 -0.258819 0.965926</xyz>
        <limit>
          <lower>0</lower>
          <upper>0.785398</upper>
          <effort>2</effort>
          <velocity>2</velocity>
        </limit>
        <dynamics>
          <damping>0.5</damping>
        </dynamics>
      </axis>
    </joint>
    <link name='hand_ring_flex_3_link'>
      <pose>0.11225 -0.991326 1.666918 -4.85507e-12 0.261799 -1.5708</pose>
      <inertial>
        <pose>0.0096 0.003 0 0 -0 0</pose>
        <mass>0.015</mass>
        <inertia>
          <ixx>0.001</ixx>
          <ixy>0</ixy>
          <ixz>0</ixz>
          <iyy>0.001</iyy>
          <iyz>0</iyz>
          <izz>0.001</izz>
        </inertia>
      </inertial>
      <collision name='hand_ring_flex_3_link_collision'>
        <pose>0 0 0 0 -0 0</pose>
        <geometry>
          <mesh>
            <scale>1 1 1</scale>
            <uri>file://tiago/hey5_description/meshes/finger_flex_tip_collision.stl</uri>
          </mesh>
        </geometry>
        <surface>
          <contact>
            <ode/>
          </contact>
          <friction>
            <ode/>
          </friction>
        </surface>
      </collision>
      <visual name='hand_ring_flex_3_link_visual'>
        <pose>0 0 0 0 -0 0</pose>
        <geometry>
          <mesh>
            <scale>1 1 1</scale>
            <uri>file://tiago/hey5_description/meshes/finger_flex_tip_collision.stl</uri>
          </mesh>
        </geometry>
        <material>
          <script>
            <name>Gazebo/Black</name>
            <uri>__default__</uri>
          </script>
        </material>
      </visual>
      <gravity>1</gravity>
      <velocity_decay>
        <linear>0</linear>
        <angular>0</angular>
      </velocity_decay>
      <self_collide>0</self_collide>
    </link>
    <joint name='hand_ring_flex_3_joint' type='revolute'>
      <child>hand_ring_flex_3_link</child>
      <parent>hand_ring_virtual_3_link</parent>
      <axis>
        <xyz>5.79713e-12 -0.258819 0.965926</xyz>
        <limit>
          <lower>0</lower>
          <upper>0.785398</upper>
          <effort>2</effort>
          <velocity>2</velocity>
        </limit>
        <dynamics>
          <damping>0.5</damping>
        </dynamics>
      </axis>
    </joint>
    <link name='hand_thumb_abd_link'>
      <pose>0.12145 -0.891175 1.7345 -1.10961e-11 -1.13446 -1.5708</pose>
      <inertial>
        <pose>-0.0132 0.0037 -0.0017 0 -0 0</pose>
        <mass>0.014</mass>
        <inertia>
          <ixx>0.001</ixx>
          <ixy>0</ixy>
          <ixz>0</ixz>
          <iyy>0.001</iyy>
          <iyz>0</iyz>
          <izz>0.001</izz>
        </inertia>
      </inertial>
      <collision name='hand_thumb_abd_link_collision'>
        <pose>0 0 0 0 -0 0</pose>
        <geometry>
          <mesh>
            <scale>1 1 1</scale>
            <uri>file://tiago/hey5_description/meshes/thumb_abd_collision.stl</uri>
          </mesh>
        </geometry>
        <surface>
          <contact>
            <ode/>
          </contact>
          <friction>
            <ode/>
          </friction>
        </surface>
      </collision>
      <visual name='hand_thumb_abd_link_visual'>
        <pose>0 0 0 0 -0 0</pose>
        <geometry>
          <mesh>
            <scale>1 1 1</scale>
            <uri>file://tiago/hey5_description/meshes/thumb_abd_collision.stl</uri>
          </mesh>
        </geometry>
        <material>
          <script>
            <name>Gazebo/Black</name>
            <uri>__default__</uri>
          </script>
        </material>
      </visual>
      <gravity>1</gravity>
      <velocity_decay>
        <linear>0</linear>
        <angular>0</angular>
      </velocity_decay>
      <self_collide>0</self_collide>
    </link>
    <joint name='hand_thumb_abd_joint' type='revolute'>
      <child>hand_thumb_abd_link</child>
      <parent>arm_7_link</parent>
      <axis>
        <xyz>-2.45579e-12 0.906308 0.422618</xyz>
        <limit>
          <lower>0</lower>
          <upper>1.5708</upper>
          <effort>2</effort>
          <velocity>2</velocity>
        </limit>
        <dynamics>
          <damping>0.5</damping>
        </dynamics>
      </axis>
    </joint>
    <link name='hand_thumb_virtual_1_link'>
      <pose>0.12445 -0.900684 1.754892 -1.14424 -1.13446 -1.5708</pose>
      <inertial>
        <pose>0.0065 0 0 0 -0 0</pose>
        <mass>0.01</mass>
        <inertia>
          <ixx>0.001</ixx>
          <ixy>0</ixy>
          <ixz>0</ixz>
          <iyy>0.001</iyy>
          <iyz>0</iyz>
          <izz>0.001</izz>
        </inertia>
      </inertial>
      <collision name='hand_thumb_virtual_1_link_collision'>
        <pose>0 0 0 0 -0 0</pose>
        <geometry>
          <box>
            <size>0.013 0.002 0.012</size>
          </box>
        </geometry>
        <surface>
          <contact>
            <ode/>
          </contact>
          <friction>
            <ode/>
          </friction>
        </surface>
      </collision>
      <visual name='hand_thumb_virtual_1_link_visual'>
        <pose>0.0065 0 0 0 -0 0</pose>
        <geometry>
          <box>
            <size>0.013 0.002 0.012</size>
          </box>
        </geometry>
        <material>
          <script>
            <name>Gazebo/Black</name>
            <uri>__default__</uri>
          </script>
        </material>
      </visual>
      <gravity>1</gravity>
      <velocity_decay>
        <linear>0</linear>
        <angular>0</angular>
      </velocity_decay>
      <self_collide>0</self_collide>
    </link>
    <joint name='hand_thumb_virtual_1_joint' type='revolute'>
      <child>hand_thumb_virtual_1_link</child>
      <parent>hand_thumb_abd_link</parent>
      <axis>
        <xyz>0.910395 0.374976 0.174854</xyz>
        <limit>
          <lower>0</lower>
          <upper>0.785398</upper>
          <effort>2</effort>
          <velocity>2</velocity>
        </limit>
        <dynamics>
          <damping>0.5</damping>
        </dynamics>
      </axis>
    </joint>
    <link name='hand_thumb_flex_1_link'>
      <pose>0.12445 -0.906178 1.766674 -1.14424 -1.13446 -1.5708</pose>
      <inertial>
        <pose>0.0047 0.0031 0 0 -0 0</pose>
        <mass>0.009</mass>
        <inertia>
          <ixx>0.001</ixx>
          <ixy>0</ixy>
          <ixz>0</ixz>
          <iyy>0.001</iyy>
          <iyz>0</iyz>
          <izz>0.001</izz>
        </inertia>
      </inertial>
      <collision name='hand_thumb_flex_1_link_collision'>
        <pose>0 0 0 0 -0 0</pose>
        <geometry>
          <mesh>
            <scale>1 1 1</scale>
            <uri>file://tiago/hey5_description/meshes/finger_flex_collision.stl</uri>
          </mesh>
        </geometry>
        <surface>
          <contact>
            <ode/>
          </contact>
          <friction>
            <ode/>
          </friction>
        </surface>
      </collision>
      <visual name='hand_thumb_flex_1_link_visual'>
        <pose>0 0 0 0 -0 0</pose>
        <geometry>
          <mesh>
            <scale>1 1 1</scale>
            <uri>file://tiago/hey5_description/meshes/finger_flex_collision.stl</uri>
          </mesh>
        </geometry>
        <material>
          <script>
            <name>Gazebo/Black</name>
            <uri>__default__</uri>
          </script>
        </material>
      </visual>
      <gravity>1</gravity>
      <velocity_decay>
        <linear>0</linear>
        <angular>0</angular>
      </velocity_decay>
      <self_collide>0</self_collide>
    </link>
    <joint name='hand_thumb_flex_1_joint' type='revolute'>
      <child>hand_thumb_flex_1_link</child>
      <parent>hand_thumb_virtual_1_link</parent>
      <axis>
        <xyz>0.910395 0.374976 0.174854</xyz>
        <limit>
          <lower>0</lower>
          <upper>0.785398</upper>
          <effort>2</effort>
          <velocity>2</velocity>
        </limit>
        <dynamics>
          <damping>0.5</damping>
        </dynamics>
      </axis>
    </joint>
    <link name='hand_thumb_virtual_2_link'>
      <pose>0.12445 -0.909982 1.774831 -1.14424 -1.13446 -1.5708</pose>
      <inertial>
        <pose>0.0065 0 0 0 -0 0</pose>
        <mass>0.01</mass>
        <inertia>
          <ixx>0.001</ixx>
          <ixy>0</ixy>
          <ixz>0</ixz>
          <iyy>0.001</iyy>
          <iyz>0</iyz>
          <izz>0.001</izz>
        </inertia>
      </inertial>
      <collision name='hand_thumb_virtual_2_link_collision'>
        <pose>0 0 0 0 -0 0</pose>
        <geometry>
          <box>
            <size>0.013 0.002 0.012</size>
          </box>
        </geometry>
        <surface>
          <contact>
            <ode/>
          </contact>
          <friction>
            <ode/>
          </friction>
        </surface>
      </collision>
      <visual name='hand_thumb_virtual_2_link_visual'>
        <pose>0.0065 0 0 0 -0 0</pose>
        <geometry>
          <box>
            <size>0.013 0.002 0.012</size>
          </box>
        </geometry>
        <material>
          <script>
            <name>Gazebo/Black</name>
            <uri>__default__</uri>
          </script>
        </material>
      </visual>
      <gravity>1</gravity>
      <velocity_decay>
        <linear>0</linear>
        <angular>0</angular>
      </velocity_decay>
      <self_collide>0</self_collide>
    </link>
    <joint name='hand_thumb_virtual_2_joint' type='revolute'>
      <child>hand_thumb_virtual_2_link</child>
      <parent>hand_thumb_flex_1_link</parent>
      <axis>
        <xyz>0.910395 0.374976 0.174854</xyz>
        <limit>
          <lower>0</lower>
          <upper>0.785398</upper>
          <effort>2</effort>
          <velocity>2</velocity>
        </limit>
        <dynamics>
          <damping>0.5</damping>
        </dynamics>
      </axis>
    </joint>
    <link name='hand_thumb_flex_2_link'>
      <pose>0.12445 -0.915476 1.786613 -1.14424 -1.13446 -1.5708</pose>
      <inertial>
        <pose>0.0096 0.003 0 0 -0 0</pose>
        <mass>0.015</mass>
        <inertia>
          <ixx>0.001</ixx>
          <ixy>0</ixy>
          <ixz>0</ixz>
          <iyy>0.001</iyy>
          <iyz>0</iyz>
          <izz>0.001</izz>
        </inertia>
      </inertial>
      <collision name='hand_thumb_flex_2_link_collision'>
        <pose>0 0 0 0 -0 0</pose>
        <geometry>
          <mesh>
            <scale>1 1 1</scale>
            <uri>file://tiago/hey5_description/meshes/finger_flex_tip_collision.stl</uri>
          </mesh>
        </geometry>
        <surface>
          <contact>
            <ode/>
          </contact>
          <friction>
            <ode/>
          </friction>
        </surface>
      </collision>
      <visual name='hand_thumb_flex_2_link_visual'>
        <pose>0 0 0 0 -0 0</pose>
        <geometry>
          <mesh>
            <scale>1 1 1</scale>
            <uri>file://tiago/hey5_description/meshes/finger_flex_tip_collision.stl</uri>
          </mesh>
        </geometry>
        <material>
          <script>
            <name>Gazebo/Black</name>
            <uri>__default__</uri>
          </script>
        </material>
      </visual>
      <gravity>1</gravity>
      <velocity_decay>
        <linear>0</linear>
        <angular>0</angular>
      </velocity_decay>
      <self_collide>0</self_collide>
    </link>
    <joint name='hand_thumb_flex_2_joint' type='revolute'>
      <child>hand_thumb_flex_2_link</child>
      <parent>hand_thumb_virtual_2_link</parent>
      <axis>
        <xyz>0.910395 0.374976 0.174854</xyz>
        <limit>
          <lower>0</lower>
          <upper>0.785398</upper>
          <effort>2</effort>
          <velocity>2</velocity>
        </limit>
        <dynamics>
          <damping>0.5</damping>
        </dynamics>
      </axis>
    </joint>
    <link name='hand_thumb_link'>
      <pose>0.10805 -0.801075 1.6965 -4.68987e-12 4.8961e-12 -1.5708</pose>
      <inertial>
        <pose>0 0 0 0 -0 0</pose>
        <mass>0.05</mass>
        <inertia>
          <ixx>0.001</ixx>
          <ixy>0</ixy>
          <ixz>0</ixz>
          <iyy>0.001</iyy>
          <iyz>0</iyz>
          <izz>0.001</izz>
        </inertia>
      </inertial>
      <collision name='hand_thumb_link_collision'>
        <pose>0 0 0 0 -0 0</pose>
        <geometry>
          <sphere>
            <radius>0.001</radius>
          </sphere>
        </geometry>
      </collision>
      <visual name='hand_thumb_link_visual'>
        <pose>0 0 0 0 -0 0</pose>
        <geometry>
          <sphere>
            <radius>0.001</radius>
          </sphere>
        </geometry>
      </visual>
      <velocity_decay>
        <linear>0</linear>
        <angular>0</angular>
      </velocity_decay>
    </link>
    <joint name='hand_thumb_joint' type='revolute'>
      <child>hand_thumb_link</child>
      <parent>arm_7_link</parent>
      <axis>
        <xyz>4.68987e-12 -4.8961e-12 1</xyz>
        <limit>
          <lower>-2.61799</lower>
          <upper>6.28319</upper>
          <effort>2</effort>
          <velocity>3.35</velocity>
        </limit>
        <dynamics>
          <damping>0.5</damping>
        </dynamics>
      </axis>
    </joint>
    <link name='head_1_link'>
      <pose>0.12 0 1.8785 0 -0 0</pose>
      <inertial>
        <pose>-0.00508 0.00237 0.07229 0 -0 0</pose>
        <mass>0.6222</mass>
        <inertia>
          <ixx>0.001192</ixx>
          <ixy>-7e-06</ixy>
          <ixz>9.6e-05</ixz>
          <iyy>0.001402</iyy>
          <iyz>4e-06</iyz>
          <izz>0.000889</izz>
        </inertia>
      </inertial>
      <collision name='head_1_link_collision'>
        <pose>0 0 0 0 -0 0</pose>
        <geometry>
          <mesh>
            <scale>1 1 1</scale>
            <uri>file://tiago/tiago_description/meshes/head/head_1_collision.dae</uri>
          </mesh>
        </geometry>
        <surface>
          <contact>
            <ode/>
          </contact>
          <friction>
            <ode>
              <mu>0.9</mu>
              <mu2>0.9</mu2>
            </ode>
          </friction>
        </surface>
      </collision>
      <visual name='head_1_link_visual'>
        <pose>0 0 0 0 -0 0</pose>
        <geometry>
          <mesh>
            <scale>1 1 1</scale>
            <uri>file://tiago/tiago_description/meshes/head/head_1.stl</uri>
          </mesh>
        </geometry>
      </visual>
      <gravity>1</gravity>
      <velocity_decay>
        <linear>0</linear>
        <angular>0</angular>
      </velocity_decay>
      <self_collide>0</self_collide>
    </link>
    <joint name='head_1_joint' type='revolute'>
      <child>head_1_link</child>
      <parent>torso_lift_link</parent>
      <axis>
        <xyz>0 0 1</xyz>
        <limit>
          <lower>-1.309</lower>
          <upper>1.309</upper>
          <effort>5.197</effort>
          <velocity>3</velocity>
        </limit>
        <dynamics>
          <damping>0.5</damping>
        </dynamics>
      </axis>
      <physics>
        <ode>
          <implicit_spring_damper>1</implicit_spring_damper>
          <cfm_damping>1</cfm_damping>
          <limit>
            <cfm>0</cfm>
            <erp>0.2</erp>
          </limit>
        </ode>
      </physics>
    </joint>
    <link name='head_2_link'>
      <pose>0.125 0 1.9765 1.5708 -0 0</pose>
      <inertial>
        <pose>0.0557879 0.0609773 1.13571e-05 0 -0 0</pose>
        <mass>0.88593</mass>
        <inertia>
          <ixx>0.00476064</ixx>
          <ixy>0.000561581</ixy>
          <ixz>1.2081e-05</ixz>
          <iyy>0.00512284</iyy>
          <iyz>9.40226e-06</iyz>
          <izz>0.00346439</izz>
        </inertia>
      </inertial>
      <collision name='head_2_link_collision'>
        <pose>0 0 0 0 -0 0</pose>
        <geometry>
          <mesh>
            <scale>1 1 1</scale>
            <uri>file://tiago/tiago_description/meshes/head/head_2_collision.dae</uri>
          </mesh>
        </geometry>
      </collision>
      <visual name='head_2_link_visual'>
        <pose>0 0 0 0 -0 0</pose>
        <geometry>
          <mesh>
            <scale>1 1 1</scale>
            <uri>file://tiago/tiago_description/meshes/head/head_2.stl</uri>
          </mesh>
        </geometry>
      </visual>
      <gravity>1</gravity>
      <velocity_decay>
        <linear>0</linear>
        <angular>0</angular>
      </velocity_decay>
      <self_collide>0</self_collide>
      <sensor name='xtion_frame_sensor' type='depth'>
        <always_on>1</always_on>
        <update_rate>30</update_rate>
        <camera name='__default__'>
          <horizontal_fov>1.01229</horizontal_fov>
          <image>
            <format>B8G8R8</format>
            <width>640</width>
            <height>480</height>
          </image>
          <clip>
            <near>0.3</near>
            <far>8</far>
          </clip>
        </camera>
        <pose>0.0908 0.08 -0.022 -1.5708 0 0</pose>
      </sensor>
    </link>
    <joint name='head_2_joint' type='revolute'>
      <child>head_2_link</child>
      <parent>head_1_link</parent>
      <axis>
        <xyz>0 -1 4.89658e-12</xyz>
        <limit>
          <lower>-1.0472</lower>
          <upper>0.785398</upper>
          <effort>2.77</effort>
          <velocity>3</velocity>
        </limit>
        <dynamics>
          <damping>0.5</damping>
        </dynamics>
      </axis>
    </joint>
    <link name='wheel_left_link'>
      <pose>0 0.2022 0.0985 -1.5708 0 0</pose>
      <inertial>
        <pose>0 0 0.00207 0 -0 0</pose>
        <mass>1.82362</mass>
        <inertia>
          <ixx>0.00499743</ixx>
          <ixy>-4.464e-08</ixy>
          <ixz>-2.245e-08</ixz>
          <iyy>0.00499742</iyy>
          <iyz>1.64e-09</iyz>
          <izz>0.0083924</izz>
        </inertia>
      </inertial>
      <collision name='wheel_left_link_collision'>
        <pose>0 0 0 0 -0 0</pose>
        <geometry>
          <cylinder>
            <length>0.04</length>
            <radius>0.0985</radius>
          </cylinder>
        </geometry>
        <surface>
          <contact>
            <ode>
              <kp>1e+06</kp>
              <kd>100</kd>
              <max_vel>1</max_vel>
              <min_depth>0.003</min_depth>
            </ode>
          </contact>
          <friction>
            <ode>
              <mu>1</mu>
              <mu2>1</mu2>
              <fdir1>1 0 0</fdir1>
            </ode>
          </friction>
        </surface>
      </collision>
      <visual name='wheel_left_link_visual'>
        <pose>0 0 0 3.14159 -0 0</pose>
        <geometry>
          <mesh>
            <scale>1 1 1</scale>
            <uri>file://tiago/pmb2_description/meshes/wheels/wheel.stl</uri>
          </mesh>
        </geometry>
        <material>
          <script>
            <name>Gazebo/DarkGrey</name>
            <uri>__default__</uri>
          </script>
        </material>
      </visual>
      <gravity>1</gravity>
      <velocity_decay>
        <linear>0</linear>
        <angular>0</angular>
      </velocity_decay>
      <self_collide>0</self_collide>
    </link>
    <joint name='wheel_left_joint' type='revolute'>
      <child>wheel_left_link</child>
      <parent>base_footprint</parent>
      <axis>
        <xyz>0 1 4.89658e-12</xyz>
        <limit>
          <lower>-1e+16</lower>
          <upper>1e+16</upper>
        </limit>
        <dynamics/>
      </axis>
    </joint>
    <link name='wheel_right_link'>
      <pose>0 -0.2022 0.0985 -1.5708 0 0</pose>
      <inertial>
        <pose>0 0 -0.00207 0 -0 0</pose>
        <mass>1.82362</mass>
        <inertia>
          <ixx>0.00499743</ixx>
          <ixy>4.464e-08</ixy>
          <ixz>-2.245e-08</ixz>
          <iyy>0.00499742</iyy>
          <iyz>-1.64e-09</iyz>
          <izz>0.0083924</izz>
        </inertia>
      </inertial>
      <collision name='wheel_right_link_collision'>
        <pose>0 0 0 0 -0 0</pose>
        <geometry>
          <cylinder>
            <length>0.04</length>
            <radius>0.0985</radius>
          </cylinder>
        </geometry>
        <surface>
          <contact>
            <ode>
              <kp>1e+06</kp>
              <kd>100</kd>
              <max_vel>1</max_vel>
              <min_depth>0.003</min_depth>
            </ode>
          </contact>
          <friction>
            <ode>
              <mu>1</mu>
              <mu2>1</mu2>
              <fdir1>1 0 0</fdir1>
            </ode>
          </friction>
        </surface>
      </collision>
      <visual name='wheel_right_link_visual'>
        <pose>0 0 0 0 -0 0</pose>
        <geometry>
          <mesh>
            <scale>1 1 1</scale>
            <uri>file://tiago/pmb2_description/meshes/wheels/wheel.stl</uri>
          </mesh>
        </geometry>
        <material>
          <script>
            <name>Gazebo/DarkGrey</name>
            <uri>__default__</uri>
          </script>
        </material>
      </visual>
      <gravity>1</gravity>
      <velocity_decay>
        <linear>0</linear>
        <angular>0</angular>
      </velocity_decay>
      <self_collide>0</self_collide>
    </link>
    <joint name='wheel_right_joint' type='revolute'>
      <child>wheel_right_link</child>
      <parent>base_footprint</parent>
      <axis>
        <xyz>0 1 4.89658e-12</xyz>
        <limit>
          <lower>-1e+16</lower>
          <upper>1e+16</upper>
        </limit>
        <dynamics/>
      </axis>
    </joint>
    <static>0</static>
    <plugin name='gazebo_hand_thumb' filename='libgazebo_underactuated_finger.so'>
      <actuatedJoint>hand_thumb_joint</actuatedJoint>
      <virtualJoint>
        <name>hand_thumb_abd_joint</name>
        <scale_factor>2.0</scale_factor>
      </virtualJoint>
      <virtualJoint>
        <name>hand_thumb_flex_1_joint</name>
        <scale_factor>2.5</scale_factor>
      </virtualJoint>
      <virtualJoint>
        <name>hand_thumb_virtual_1_joint</name>
        <scale_factor>3.0</scale_factor>
      </virtualJoint>
      <virtualJoint>
        <name>hand_thumb_flex_2_joint</name>
        <scale_factor>3.5</scale_factor>
      </virtualJoint>
      <virtualJoint>
        <name>hand_thumb_virtual_2_joint</name>
        <scale_factor>3.0</scale_factor>
      </virtualJoint>
    </plugin>
    <plugin name='gazebo_hand_index' filename='libgazebo_underactuated_finger.so'>
      <actuatedJoint>hand_index_joint</actuatedJoint>
      <virtualJoint>
        <name>hand_index_abd_joint</name>
        <scale_factor>5.0</scale_factor>
      </virtualJoint>
      <virtualJoint>
        <name>hand_index_flex_1_joint</name>
        <scale_factor>2.5</scale_factor>
      </virtualJoint>
      <virtualJoint>
        <name>hand_index_virtual_1_joint</name>
        <scale_factor>3.0</scale_factor>
      </virtualJoint>
      <virtualJoint>
        <name>hand_index_flex_2_joint</name>
        <scale_factor>3.5</scale_factor>
      </virtualJoint>
      <virtualJoint>
        <name>hand_index_virtual_2_joint</name>
        <scale_factor>3.5</scale_factor>
      </virtualJoint>
      <virtualJoint>
        <name>hand_index_flex_3_joint</name>
        <scale_factor>4.0</scale_factor>
      </virtualJoint>
    </plugin>
    <plugin name='gazebo_hand_middle' filename='libgazebo_underactuated_finger.so'>
      <actuatedJoint>hand_mrl_joint</actuatedJoint>
      <virtualJoint>
        <name>hand_middle_flex_1_joint</name>
        <scale_factor>2.5</scale_factor>
      </virtualJoint>
      <virtualJoint>
        <name>hand_middle_virtual_1_joint</name>
        <scale_factor>3.0</scale_factor>
      </virtualJoint>
      <virtualJoint>
        <name>hand_middle_flex_2_joint</name>
        <scale_factor>3.5</scale_factor>
      </virtualJoint>
      <virtualJoint>
        <name>hand_middle_virtual_2_joint</name>
        <scale_factor>3.5</scale_factor>
      </virtualJoint>
      <virtualJoint>
        <name>hand_middle_flex_3_joint</name>
        <scale_factor>4.0</scale_factor>
      </virtualJoint>
    </plugin>
    <plugin name='gazebo_hand_ring' filename='libgazebo_underactuated_finger.so'>
      <actuatedJoint>hand_mrl_joint</actuatedJoint>
      <virtualJoint>
        <name>hand_ring_flex_1_joint</name>
        <scale_factor>2.5</scale_factor>
      </virtualJoint>
      <virtualJoint>
        <name>hand_ring_virtual_1_joint</name>
        <scale_factor>3.0</scale_factor>
      </virtualJoint>
      <virtualJoint>
        <name>hand_ring_flex_2_joint</name>
        <scale_factor>3.5</scale_factor>
      </virtualJoint>
      <virtualJoint>
        <name>hand_ring_virtual_2_joint</name>
        <scale_factor>3.5</scale_factor>
      </virtualJoint>
      <virtualJoint>
        <name>hand_ring_flex_3_joint</name>
        <scale_factor>4.0</scale_factor>
      </virtualJoint>
    </plugin>
    <plugin name='gazebo_hand_little' filename='libgazebo_underactuated_finger.so'>
      <actuatedJoint>hand_mrl_joint</actuatedJoint>
      <virtualJoint>
        <name>hand_little_flex_1_joint</name>
        <scale_factor>2.5</scale_factor>
      </virtualJoint>
      <virtualJoint>
        <name>hand_little_virtual_1_joint</name>
        <scale_factor>3.0</scale_factor>
      </virtualJoint>
      <virtualJoint>
        <name>hand_little_flex_2_joint</name>
        <scale_factor>3.5</scale_factor>
      </virtualJoint>
      <virtualJoint>
        <name>hand_little_virtual_2_joint</name>
        <scale_factor>3.5</scale_factor>
      </virtualJoint>
      <virtualJoint>
        <name>hand_little_flex_3_joint</name>
        <scale_factor>4.0</scale_factor>
      </virtualJoint>
    </plugin>
  </model>
</sdf>
